Workbook

Sheet Summary
A1: Property Details | D1: Acquisition Loan Information | G1: Summary Details | J1: Sources (at Close)
A2: Year Built | B2: 2010 | D2: Loan Amount | E2: =E3*B20 -> 26000000 | G2: Purchase Price | H2: =B20 -> 40000000 | J2: Equity | K2: =K11-K3 -> 14710000
A3: Number of Units | B3: 100 | D3: LTV | E3: 0.65 | G3: Going-In Cap Rate | H3: =B24 -> 0.05 | J3: Acquisition Loan Proceeds | K3: =E2 -> 26000000
A4: Number of Buildings | B4: 10 | D4: Going-In DSCR | E4: 1.25 | G4: Purchase Price/Unit | H4: =B21 -> 400000 | J4: Total Sources | K4: =SUM(K2:K3) -> 40710000
A5: Net Rentable SF | B5: 150000 | D5: Going-In Debt Yield | E5: 0.075 | G5: Purchase Price/SF | H5: =H2/B5 -> 266.66667
A6: Average Unit Size | B6: =+B5/B3 -> 1500 | D6: Interest Rate | E6: 0.04 | G6: Total Cost of Project | H6: 42000000 | J6: Uses (at Close)
A7: Net Acres | B7: 5 | D7: Interest-Only Period | E7: 36 | G7: Total Cost/Unit | H7: =H6/B3 -> 420000 | J7: Purchase Price | K7: =B20 -> 40000000
A8: Units Per Acre | B8: =+B3/B7 -> 20 | D8: Loan Fee (%) | E8: 0.01 | J8: Closing Costs | K8: =B22 -> 150000
A9: Street Address | B9: 555 Main Street | D9: Amortization | E9: 360 | G9: Renovation Details | J9: Up-Front Working Capital | K9: =B23 -> 300000
A10: City/State/Zip | B10: San Francisco, CA | D10: Term | E10: 60 | G10: Total Construction Costs | H10: 1000000 | J10: Acquisition Loan Fees | K10: =E8*E2 -> 260000
G11: Total Construction Costs/Unit | H11: =H10/B3 -> 10000 | J11: Total Uses | K11: =SUM(K7:K10) -> 40710000
A12: Parking Information | D12: Refinance Information | G12: Exterior Renovation Costs | H12: 500000
A13: Uncovered Spaces | B13: 100 | D13: Refinance Month | E13: =E10 -> 60 | G13: Exterior Renovation Costs/Unit | H13: =H12/B3 -> 5000 | J13: Additional Equity Requirements (Post-Close)
A14: Carport Spaces | B14: 40 | D14: Loan Amount | E14: 30000000 | G14: Interior Renovation Costs | H14: 500000 | J14: Additional Equity Required | K14: 0
A15: Garage Spaces | B15: 25 | D15: Cap Rate Used For Valuation | E15: 0.06 | G15: Interior Renovation Costs/Unit | H15: =H14/B3 -> 5000
A16: Total Spaces | B16: =SUM(B13:B15) -> 165 | D16: LTV | E16: 0.65 | G16: Return on Cost | H16: 0.15 | J16: Sale Information
A17: Total Spaces/Unit | B17: =B16/B3 -> 1.65 | D17: Going-In DSCR | E17: 1.25 | J17: Closing Costs (%) | K17: 0.03
D18: Going-In Debt Yield | E18: 0.075 | G18: Sale Details | J18: Exit Cap Rate | K18: 0.06
A19: Acquisition Information | D19: Interest Rate | E19: 0.04 | G19: Exit Cap Rate | H19: 0.06 | J19: Hold Period | K19: 120
A20: Purchase Price | B20: 40000000 | D20: Interest-Only Period | E20: 36 | G20: Cap Rate Expansion/Year | H20: 0.001
A21: Purchase Price/Unit | B21: =B20/B3 -> 400000 | D21: Loan Fee (%) | E21: 0.01 | G21: Sale Price | H21: 50000000 | J21: Return Metrics
A22: Closing Costs | B22: 150000 | D22: Amortization | E22: 360 | G22: Sale Price/Unit | H22: =H21/B3 -> 500000 | J22: Internal Rate of Return (IRR) | K22: 0.16
A23: Up-Front Working Capital | B23: 300000 | G23: Costs of Sale | H23: 250000 | J23: Equity Multiple | K23: 2.5
A24: Going-In Cap Rate | B24: 0.05 | G24: Value CAGR | H24: 0.03 | J24: Average Cash-on-Cash | K24: 0.08
A25: Property Closing Date | B25: 44227 | G25: Levered IRR | H25: 0.16
G26: Levered Equity Multiple | H26: 2.5
G27: Levered Average Cash-on-Cash | H27: 0.08

Sheet Revenue
A1: Current In-Place Rents | G1: Stabilized Rents | M1: Renovation Premium | O1: Other Income/Unit/Month | S1: 1 | T1: =S1+1 -> 2 | U1: =T1+1 -> 3 | V1: =U1+1 -> 4 | W1: =V1+1 -> 5 | X1: =W1+1 -> 6 | Y1: =X1+1 -> 7 | Z1: =Y1+1 -> 8 | AA1: =Z1+1 -> 9 | ... AC1: =AB1+1 -> 11 | AF1: 1 | AG1: =AF1+1 -> 2 | AH1: =AG1+1 -> 3 | AI1: =AH1+1 -> 4 | AJ1: =AI1+1 -> 5 | AK1: =AJ1+1 -> 6 | AL1: =AK1+1 -> 7 | AM1: =AL1+1 -> 8 | AN1: =AM1+1 -> 9 | ... FG1: =FF1+1 -> 132
A2: # of Units | B2: Unit Type | C2: SF | D2: Rent/Month | E2: $/SF | G2: # of Units | H2: Unit Type | I2: SF | J2: Rent/Month | K2: $/SF | M2: Premium | O2: Laundry Income | P2: 10 | R2: Physical Vacancy | S2: 0.06 | T2: 0.055 | U2: 0.05 | V2: 0.05 | W2: 0.05 | X2: 0.05 | Y2: 0.05 | Z2: 0.05 | AA2: 0.05 | AB2: 0.05 | AC2: 0.05 | AE2: In-Place Rents | AF2: =A23*D23 -> 245000 | AG2: =AF2*(1+HLOOKUP(ROUNDUP(AF$1/12,0),$S$8:$AC$9,2,0))^(1/12) -> 245998.16 | AH2: =AG2*(1+HLOOKUP(ROUNDUP(AG$1/12,0),$S$8:$AC$9,2,0))^(1/12) -> 247000.39 | AI2: =AH2*(1+HLOOKUP(ROUNDUP(AH$1/12,0),$S$8:$AC$9,2,0))^(1/12) -> 248006.7 | AJ2: =AI2*(1+HLOOKUP(ROUNDUP(AI$1/12,0),$S$8:$AC$9,2,0))^(1/12) -> 249017.11 | AK2: =AJ2*(1+HLOOKUP(ROUNDUP(AJ$1/12,0),$S$8:$AC$9,2,0))^(1/12) -> 250031.63 | AL2: =AK2*(1+HLOOKUP(ROUNDUP(AK$1/12,0),$S$8:$AC$9,2,0))^(1/12) -> 251050.29 | AM2: =AL2*(1+HLOOKUP(ROUNDUP(AL$1/12,0),$S$8:$AC$9,2,0))^(1/12) -> 252073.1 | AN2: =AM2*(1+HLOOKUP(ROUNDUP(AM$1/12,0),$S$8:$AC$9,2,0))^(1/12) -> 253100.08 | ... FG2: =FF2*(1+HLOOKUP(ROUNDUP(FF$1/12,0),$S$8:$AC$9,2,0))^(1/12) -> 348220.21
A3: 50 | B3: 1BR - 1BA | C3: 1000 | D3: 1900 | E3: =IFERROR(D3/C3,0) -> 1.9 | G3: =A3 -> 50 | H3: =B3 -> 1BR - 1BA | I3: =C3 -> 1000 | J3: 2000 | K3: =IFERROR(J3/I3,0) -> 2 | M3: =J3-D3 -> 100 | O3: Late Fees | P3: 10 | R3: Bad Debt | S3: 0.01 | T3: 0.0075 | U3: 0.005 | V3: 0.005 | W3: 0.005 | X3: 0.005 | Y3: 0.005 | Z3: 0.005 | AA3: 0.005 | AB3: 0.005 | AC3: 0.005 | AE3: Stabilized Rents | AF3: =G23*J23 -> 256000 | AG3: =AF3*(1+HLOOKUP(ROUNDUP(AF$1/12,0),$S$8:$AC$9,2,0))^(1/12) -> 257042.98 | AH3: =AG3*(1+HLOOKUP(ROUNDUP(AG$1/12,0),$S$8:$AC$9,2,0))^(1/12) -> 258090.2 | AI3: =AH3*(1+HLOOKUP(ROUNDUP(AH$1/12,0),$S$8:$AC$9,2,0))^(1/12) -> 259141.69 | AJ3: =AI3*(1+HLOOKUP(ROUNDUP(AI$1/12,0),$S$8:$AC$9,2,0))^(1/12) -> 260197.47 | AK3: =AJ3*(1+HLOOKUP(ROUNDUP(AJ$1/12,0),$S$8:$AC$9,2,0))^(1/12) -> 261257.54 | AL3: =AK3*(1+HLOOKUP(ROUNDUP(AK$1/12,0),$S$8:$AC$9,2,0))^(1/12) -> 262321.94 | AM3: =AL3*(1+HLOOKUP(ROUNDUP(AL$1/12,0),$S$8:$AC$9,2,0))^(1/12) -> 263390.67 | AN3: =AM3*(1+HLOOKUP(ROUNDUP(AM$1/12,0),$S$8:$AC$9,2,0))^(1/12) -> 264463.76 | ... FG3: =FF3*(1+HLOOKUP(ROUNDUP(FF$1/12,0),$S$8:$AC$9,2,0))^(1/12) -> 363854.59
A4: 60 | B4: 2BR - 2BA | C4: 1500 | D4: 2500 | E4: =IFERROR(D4/C4,0) -> 1.6666667 | G4: =A4 -> 60 | H4: =B4 -> 2BR - 2BA | I4: =C4 -> 1500 | J4: 2600 | K4: =IFERROR(J4/I4,0) -> 1.7333333 | M4: =J4-D4 -> 100 | O4: Pet Rent | P4: 25 | R4: Concessions | S4: 0.01 | T4: 0.005 | U4: 0 | V4: 0 | W4: 0 | X4: 0 | Y4: 0 | Z4: 0 | AA4: 0 | AB4: 0 | AC4: 0 | AE4: % of Stabilized Units | AF4: =IF(AF1>=$P$16,1,IF(AND(AF1>=$P$15,AF1<$P$16),(AF1-$P$15+1)/$P$17,0)) -> 0 | AG4: =IF(AG1>=$P$16,1,IF(AND(AG1>=$P$15,AG1<$P$16),(AG1-$P$15+1)/$P$17,0)) -> 0 | AH4: =IF(AH1>=$P$16,1,IF(AND(AH1>=$P$15,AH1<$P$16),(AH1-$P$15+1)/$P$17,0)) -> 0 | AI4: =IF(AI1>=$P$16,1,IF(AND(AI1>=$P$15,AI1<$P$16),(AI1-$P$15+1)/$P$17,0)) -> 0 | AJ4: =IF(AJ1>=$P$16,1,IF(AND(AJ1>=$P$15,AJ1<$P$16),(AJ1-$P$15+1)/$P$17,0)) -> 0.090909091 | AK4: =IF(AK1>=$P$16,1,IF(AND(AK1>=$P$15,AK1<$P$16),(AK1-$P$15+1)/$P$17,0)) -> 0.18181818 | AL4: =IF(AL1>=$P$16,1,IF(AND(AL1>=$P$15,AL1<$P$16),(AL1-$P$15+1)/$P$17,0)) -> 0.27272727 | AM4: =IF(AM1>=$P$16,1,IF(AND(AM1>=$P$15,AM1<$P$16),(AM1-$P$15+1)/$P$17,0)) -> 0.36363636 | ... FG4: =IF(FG1>=$P$16,1,IF(AND(FG1>=$P$15,FG1<$P$16),(FG1-$P$15+1)/$P$17,0)) -> 1
A5: 0 | B5: 2BR - 2BA | C5: 0 | D5: 0 | E5: =IFERROR(D5/C5,0) -> 0 | G5: =A5 -> 0 | H5: =B5 -> 2BR - 2BA | I5: =C5 -> 0 | J5: 0 | K5: =IFERROR(J5/I5,0) -> 0 | M5: =J5-D5 -> 0 | O5: Pet Fees | P5: 5 | R5: Other Loss | S5: 0 | T5: 0 | U5: 0 | V5: 0 | W5: 0 | X5: 0 | Y5: 0 | Z5: 0 | AA5: 0 | AB5: 0 | AC5: 0 | AE5: Total Potential Rental Revenue | AF5: =AF3*AF4+AF2*(1-AF4) -> 245000 | AG5: =AG3*AG4+AG2*(1-AG4) -> 245998.16 | AH5: =AH3*AH4+AH2*(1-AH4) -> 247000.39 | AI5: =AI3*AI4+AI2*(1-AI4) -> 248006.7 | AJ5: =AJ3*AJ4+AJ2*(1-AJ4) -> 250033.5 | AK5: =AK3*AK4+AK2*(1-AK4) -> 252072.71 | AL5: =AL3*AL4+AL2*(1-AL4) -> 254124.38 | AM5: =AM3*AM4+AM2*(1-AM4) -> 256188.58 | ... FG5: =FG3*FG4+FG2*(1-FG4) -> 363854.59
A6: 0 | B6: 2BR - 2BA | C6: 0 | D6: 0 | E6: =IFERROR(D6/C6,0) -> 0 | G6: =A6 -> 0 | H6: =B6 -> 2BR - 2BA | I6: =C6 -> 0 | J6: 0 | K6: =IFERROR(J6/I6,0) -> 0 | M6: =J6-D6 -> 0 | O6: Garage Income | P6: 0 | R6: Economic Vacancy | S6: =SUM(S2:S5) -> 0.08 | T6: =SUM(T2:T5) -> 0.0675 | U6: =SUM(U2:U5) -> 0.055 | V6: =SUM(V2:V5) -> 0.055 | W6: =SUM(W2:W5) -> 0.055 | X6: =SUM(X2:X5) -> 0.055 | Y6: =SUM(Y2:Y5) -> 0.055 | Z6: =SUM(Z2:Z5) -> 0.055 | ... AC6: =SUM(AC2:AC5) -> 0.055
A7: 0 | B7: 2BR - 2BA | C7: 0 | D7: 0 | E7: =IFERROR(D7/C7,0) -> 0 | G7: =A7 -> 0 | H7: =B7 -> 2BR - 2BA | I7: =C7 -> 0 | J7: 0 | K7: =IFERROR(J7/I7,0) -> 0 | M7: =J7-D7 -> 0 | O7: Storage Income | P7: 0
A8: 0 | B8: 2BR - 2BA | C8: 0 | D8: 0 | E8: =IFERROR(D8/C8,0) -> 0 | G8: =A8 -> 0 | H8: =B8 -> 2BR - 2BA | I8: =C8 -> 0 | J8: 0 | K8: =IFERROR(J8/I8,0) -> 0 | M8: =J8-D8 -> 0 | O8: Forfeited Deposits | P8: 5 | S8: 1 | T8: =S8+1 -> 2 | U8: =T8+1 -> 3 | V8: =U8+1 -> 4 | W8: =V8+1 -> 5 | X8: =W8+1 -> 6 | Y8: =X8+1 -> 7 | Z8: =Y8+1 -> 8 | AA8: =Z8+1 -> 9 | ... AC8: =AB8+1 -> 11
A9: 0 | B9: 2BR - 2BA | C9: 0 | D9: 0 | E9: =IFERROR(D9/C9,0) -> 0 | G9: =A9 -> 0 | H9: =B9 -> 2BR - 2BA | I9: =C9 -> 0 | J9: 0 | K9: =IFERROR(J9/I9,0) -> 0 | M9: =J9-D9 -> 0 | O9: Other Charges | P9: 0 | R9: Market Rent Growth | S9: 0.05 | T9: 0.04 | U9: 0.03 | V9: 0.03 | W9: 0.03 | X9: 0.03 | Y9: 0.03 | Z9: 0.03 | AA9: 0.03 | AB9: 0.03 | AC9: 0.03
A10: 0 | B10: 2BR - 2BA | C10: 0 | D10: 0 | E10: =IFERROR(D10/C10,0) -> 0 | G10: =A10 -> 0 | H10: =B10 -> 2BR - 2BA | I10: =C10 -> 0 | J10: 0 | K10: =IFERROR(J10/I10,0) -> 0 | M10: =J10-D10 -> 0 | O10: Other Charges | P10: 0 | R10: Other Income Growth | S10: 0.03 | T10: 0.03 | U10: 0.03 | V10: 0.03 | W10: 0.03 | X10: 0.03 | Y10: 0.03 | Z10: 0.03 | AA10: 0.03 | AB10: 0.03 | AC10: 0.03
A11: 0 | B11: 2BR - 2BA | C11: 0 | D11: 0 | E11: =IFERROR(D11/C11,0) -> 0 | G11: =A11 -> 0 | H11: =B11 -> 2BR - 2BA | I11: =C11 -> 0 | J11: 0 | K11: =IFERROR(J11/I11,0) -> 0 | M11: =J11-D11 -> 0 | O11: Other Charges | P11: 0
A12: 0 | B12: 2BR - 2BA | C12: 0 | D12: 0 | E12: =IFERROR(D12/C12,0) -> 0 | G12: =A12 -> 0 | H12: =B12 -> 2BR - 2BA | I12: =C12 -> 0 | J12: 0 | K12: =IFERROR(J12/I12,0) -> 0 | M12: =J12-D12 -> 0 | O12: Total | P12: =SUM(P2:P11) -> 55
A13: 0 | B13: 2BR - 2BA | C13: 0 | D13: 0 | E13: =IFERROR(D13/C13,0) -> 0 | G13: =A13 -> 0 | H13: =B13 -> 2BR - 2BA | I13: =C13 -> 0 | J13: 0 | K13: =IFERROR(J13/I13,0) -> 0 | M13: =J13-D13 -> 0
A14: 0 | B14: 2BR - 2BA | C14: 0 | D14: 0 | E14: =IFERROR(D14/C14,0) -> 0 | G14: =A14 -> 0 | H14: =B14 -> 2BR - 2BA | I14: =C14 -> 0 | J14: 0 | K14: =IFERROR(J14/I14,0) -> 0 | M14: =J14-D14 -> 0 | O14: Rent Increase Timing
A15: 0 | B15: 2BR - 2BA | C15: 0 | D15: 0 | E15: =IFERROR(D15/C15,0) -> 0 | G15: =A15 -> 0 | H15: =B15 -> 2BR - 2BA | I15: =C15 -> 0 | J15: 0 | K15: =IFERROR(J15/I15,0) -> 0 | M15: =J15-D15 -> 0 | O15: Month Start | P15: 5
A16: 0 | B16: 2BR - 2BA | C16: 0 | D16: 0 | E16: =IFERROR(D16/C16,0) -> 0 | G16: =A16 -> 0 | H16: =B16 -> 2BR - 2BA | I16: =C16 -> 0 | J16: 0 | K16: =IFERROR(J16/I16,0) -> 0 | M16: =J16-D16 -> 0 | O16: Month End | P16: 15
A17: 0 | B17: 2BR - 2BA | C17: 0 | D17: 0 | E17: =IFERROR(D17/C17,0) -> 0 | G17: =A17 -> 0 | H17: =B17 -> 2BR - 2BA | I17: =C17 -> 0 | J17: 0 | K17: =IFERROR(J17/I17,0) -> 0 | M17: =J17-D17 -> 0 | O17: Rent Increase Period | P17: =P16-P15+1 -> 11
A18: 0 | B18: 2BR - 2BA | C18: 0 | D18: 0 | E18: =IFERROR(D18/C18,0) -> 0 | G18: =A18 -> 0 | H18: =B18 -> 2BR - 2BA | I18: =C18 -> 0 | J18: 0 | K18: =IFERROR(J18/I18,0) -> 0 | M18: =J18-D18 -> 0
A19: 0 | B19: 2BR - 2BA | C19: 0 | D19: 0 | E19: =IFERROR(D19/C19,0) -> 0 | G19: =A19 -> 0 | H19: =B19 -> 2BR - 2BA | I19: =C19 -> 0 | J19: 0 | K19: =IFERROR(J19/I19,0) -> 0 | M19: =J19-D19 -> 0
A20: 0 | B20: 2BR - 2BA | C20: 0 | D20: 0 | E20: =IFERROR(D20/C20,0) -> 0 | G20: =A20 -> 0 | H20: =B20 -> 2BR - 2BA | I20: =C20 -> 0 | J20: 0 | K20: =IFERROR(J20/I20,0) -> 0 | M20: =J20-D20 -> 0
A21: 0 | B21: 2BR - 2BA | C21: 0 | D21: 0 | E21: =IFERROR(D21/C21,0) -> 0 | G21: =A21 -> 0 | H21: =B21 -> 2BR - 2BA | I21: =C21 -> 0 | J21: 0 | K21: =IFERROR(J21/I21,0) -> 0 | M21: =J21-D21 -> 0
A22: 0 | B22: 2BR - 2BA | C22: 0 | D22: 0 | E22: =IFERROR(D22/C22,0) -> 0 | G22: =A22 -> 0 | H22: =B22 -> 2BR - 2BA | I22: =C22 -> 0 | J22: 0 | K22: =IFERROR(J22/I22,0) -> 0 | M22: =J22-D22 -> 0
A23: =SUM(A3:A22) -> 110 | C23: =SUMPRODUCT(C3:C22,$A$3:$A$22)/$A$23 -> 1272.7273 | D23: =SUMPRODUCT(D3:D22,$A$3:$A$22)/$A$23 -> 2227.2727 | E23: =IFERROR(D23/C23,0) -> 1.75 | G23: =SUM(G3:G22) -> 110 | I23: =SUMPRODUCT(I3:I22,$G$3:$G$22)/$G$23 -> 1272.7273 | J23: =SUMPRODUCT(J3:J22,$G$3:$G$22)/$G$23 -> 2327.2727 | K23: =IFERROR(J23/I23,0) -> 1.8285714 | M23: =SUMPRODUCT(M3:M22,$G$3:$G$22)/$G$23 -> 100

Sheet Expenses
A1: T-12 Operating Expenses | E1: Hold Period Operating Expenses | J1: Property Tax Growth Rates
A2: Item | B2: Total | C2: $/Unit/Year | E2: Item | F2: Total | G2: $/Unit/Year | J2: 1 | K2: =J2+1 -> 2 | L2: =K2+1 -> 3 | M2: =L2+1 -> 4 | N2: =M2+1 -> 5 | O2: =N2+1 -> 6 | P2: =O2+1 -> 7 | Q2: =P2+1 -> 8 | R2: =Q2+1 -> 9 | ... T2: =S2+1 -> 11
A3: Payroll | B3: 190000 | C3: =B3/Revenue!$A$23 -> 1727.2727 | E3: Payroll | F3: =G3*Revenue!$A$23 -> 198000 | G3: 1800 | J3: 0.1 | K3: 0.05 | L3: 0.03 | M3: 0.03 | N3: 0.03 | O3: 0.03 | P3: 0.03 | Q3: 0.03 | R3: 0.03 | S3: 0.03 | T3: 0.03
A4: General & Administrative | B4: 30000 | C4: =B4/Revenue!$A$23 -> 272.72727 | E4: General & Administrative | F4: =G4*Revenue!$A$23 -> 30250 | G4: 275
A5: Marketing | B5: 25000 | C5: =B5/Revenue!$A$23 -> 227.27273 | E5: Marketing | F5: =G5*Revenue!$A$23 -> 24750 | G5: 225 | J5: Hold Period Property Taxes
A6: Repairs & Maintenance | B6: 60000 | C6: =B6/Revenue!$A$23 -> 545.45455 | E6: Repairs & Maintenance | F6: =G6*Revenue!$A$23 -> 60500 | G6: 550 | J6: 1 | K6: =J6+1 -> 2 | L6: =K6+1 -> 3 | M6: =L6+1 -> 4 | N6: =M6+1 -> 5 | O6: =N6+1 -> 6 | P6: =O6+1 -> 7 | Q6: =P6+1 -> 8 | R6: =Q6+1 -> 9 | ... T6: =S6+1 -> 11
A7: Turnover Costs | B7: 40000 | C7: =B7/Revenue!$A$23 -> 363.63636 | E7: Turnover Costs | F7: =G7*Revenue!$A$23 -> 41250 | G7: 375 | I7: Assessed Property Value | J7: =IF(B18="Yes",Summary!B20*Expenses!B19,Expenses!B20*(1+Expenses!J3)) -> 38500000 | K7: =J7*(1+K3) -> 40425000 | L7: =K7*(1+L3) -> 41637750 | M7: =L7*(1+M3) -> 42886882 | N7: =M7*(1+N3) -> 44173489 | O7: =N7*(1+O3) -> 45498694 | P7: =O7*(1+P3) -> 46863654 | Q7: =P7*(1+Q3) -> 48269564 | R7: =Q7*(1+R3) -> 49717651 | ... T7: =S7*(1+T3) -> 52745456
A8: Contract Services | B8: 25000 | C8: =B8/Revenue!$A$23 -> 227.27273 | E8: Contract Services | F8: =G8*Revenue!$A$23 -> 24750 | G8: 225 | I8: Property Taxes | J8: =J7*$B$17 -> 385000 | K8: =K7*$B$17 -> 404250 | L8: =L7*$B$17 -> 416377.5 | M8: =M7*$B$17 -> 428868.83 | N8: =N7*$B$17 -> 441734.89 | O8: =O7*$B$17 -> 454986.94 | P8: =P7*$B$17 -> 468636.54 | Q8: =Q7*$B$17 -> 482695.64 | ... T8: =T7*$B$17 -> 527454.56
A9: Utilities | B9: 60000 | C9: =B9/Revenue!$A$23 -> 545.45455 | E9: Utilities | F9: =G9*Revenue!$A$23 -> 60500 | G9: 550 | I9: Fixed Charge Assessments | J9: =B21*(1+J3) -> 27500 | K9: =J9*(1+K3) -> 28875 | L9: =K9*(1+L3) -> 29741.25 | M9: =L9*(1+M3) -> 30633.488 | N9: =M9*(1+N3) -> 31552.492 | O9: =N9*(1+O3) -> 32499.067 | P9: =O9*(1+P3) -> 33474.039 | Q9: =P9*(1+Q3) -> 34478.26 | R9: =Q9*(1+R3) -> 35512.608 | ... T9: =S9*(1+T3) -> 37675.326
A10: Utility Bill-Back | B10: -50000 | C10: =B10/Revenue!$A$23 -> -454.54545 | E10: Utility Bill-Back | F10: =G10*Revenue!$A$23 -> -52250 | G10: -475 | I10: Total Property Taxes | J10: =SUM(J8:J9) -> 412500 | K10: =SUM(K8:K9) -> 433125 | L10: =SUM(L8:L9) -> 446118.75 | M10: =SUM(M8:M9) -> 459502.31 | N10: =SUM(N8:N9) -> 473287.38 | O10: =SUM(O8:O9) -> 487486 | P10: =SUM(P8:P9) -> 502110.58 | Q10: =SUM(Q8:Q9) -> 517173.9 | ... T10: =SUM(T8:T9) -> 565129.89
A11: Property Management Fee | B11: 120000 | C11: =B11/Revenue!$A$23 -> 1090.9091 | E11: Property Management Fee | F11: =G11*Revenue!$A$23 -> 0 | G11: 0
A12: Property Taxes | B12: 275000 | C12: =B12/Revenue!$A$23 -> 2500 | E12: Property Taxes | F12: =J10 -> 412500 | G12: =F12/Revenue!A23 -> 3750
A13: Insurance | B13: 50000 | C13: =B13/Revenue!$A$23 -> 454.54545 | E13: Insurance | F13: =G13*Revenue!$A$23 -> 49500 | G13: 450
A14: Total | B14: =SUM(B3:B13) -> 825000 | C14: =B14/Revenue!$A$23 -> 7500 | E14: Total | F14: =SUM(F3:F13) -> 849750 | G14: =F14/Revenue!$A$23 -> 7725
A16: Property Tax Information | E16: Other Expense Assumptions
A17: Millage Rate | B17: 0.01 | E17: Annual Expense Growth | F17: 0.03
A18: Reassessed Upon Sale | B18: No | E18: Capital Expense Reserves/Unit | F18: 300
A19: % of Value Assessed | B19: 1 | E19: Property Management Fee | F19: 0.04
A20: Current Assessed Value | B20: 35000000
A21: Fixed Charge Assessments | B21: 25000

Sheet Construction Budget
H1: 1 | I1: =H1+1 -> 2 | J1: =I1+1 -> 3 | K1: =J1+1 -> 4 | L1: =K1+1 -> 5 | M1: =L1+1 -> 6 | N1: =M1+1 -> 7 | O1: =N1+1 -> 8 | P1: =O1+1 -> 9 | ... EI1: =EH1+1 -> 132
H2: =ROUNDUP(H1/12,0) -> 1 | I2: =ROUNDUP(I1/12,0) -> 1 | J2: =ROUNDUP(J1/12,0) -> 1 | K2: =ROUNDUP(K1/12,0) -> 1 | L2: =ROUNDUP(L1/12,0) -> 1 | M2: =ROUNDUP(M1/12,0) -> 1 | N2: =ROUNDUP(N1/12,0) -> 1 | O2: =ROUNDUP(O1/12,0) -> 1 | ... EI2: =ROUNDUP(EI1/12,0) -> 11
B3: Exterior Renovation Budget | EI3: 0
A4: Check | B4: Item | C4: Total | D4: Per Unit | E4: Month Start | F4: Month End | G4: Total Months
A5: =IF(ABS(SUM(H5:EI5)-C5)<0.0001,"OK","ERROR") -> OK | B5: Exterior Painting | C5: 500000 | D5: =C5/Revenue!$A$23 -> 4545.4545 | E5: 2 | F5: 5 | G5: =F5-E5+1 -> 4 | H5: =IF(AND(H$1>=$E5,H$1<=$F5),$C5/$G5,0) -> 0 | I5: =IF(AND(I$1>=$E5,I$1<=$F5),$C5/$G5,0) -> 125000 | J5: =IF(AND(J$1>=$E5,J$1<=$F5),$C5/$G5,0) -> 125000 | K5: =IF(AND(K$1>=$E5,K$1<=$F5),$C5/$G5,0) -> 125000 | L5: =IF(AND(L$1>=$E5,L$1<=$F5),$C5/$G5,0) -> 125000 | M5: =IF(AND(M$1>=$E5,M$1<=$F5),$C5/$G5,0) -> 0 | N5: =IF(AND(N$1>=$E5,N$1<=$F5),$C5/$G5,0) -> 0 | O5: =IF(AND(O$1>=$E5,O$1<=$F5),$C5/$G5,0) -> 0 | ... EI5: =IF(AND(EI$1>=$E5,EI$1<=$F5),$C5/$G5,0) -> 0
A6: =IF(ABS(SUM(H6:EI6)-C6)<0.0001,"OK","ERROR") -> OK | B6: Fitness Center Renovation | C6: 250000 | D6: =C6/Revenue!$A$23 -> 2272.7273 | E6: 3 | F6: 7 | G6: =F6-E6+1 -> 5 | H6: =IF(AND(H$1>=$E6,H$1<=$F6),$C6/$G6,0) -> 0 | I6: =IF(AND(I$1>=$E6,I$1<=$F6),$C6/$G6,0) -> 0 | J6: =IF(AND(J$1>=$E6,J$1<=$F6),$C6/$G6,0) -> 50000 | K6: =IF(AND(K$1>=$E6,K$1<=$F6),$C6/$G6,0) -> 50000 | L6: =IF(AND(L$1>=$E6,L$1<=$F6),$C6/$G6,0) -> 50000 | M6: =IF(AND(M$1>=$E6,M$1<=$F6),$C6/$G6,0) -> 50000 | N6: =IF(AND(N$1>=$E6,N$1<=$F6),$C6/$G6,0) -> 50000 | O6: =IF(AND(O$1>=$E6,O$1<=$F6),$C6/$G6,0) -> 0 | ... EI6: =IF(AND(EI$1>=$E6,EI$1<=$F6),$C6/$G6,0) -> 0
A7: =IF(ABS(SUM(H7:EI7)-C7)<0.0001,"OK","ERROR") -> OK | B7: Leasing Center Renovation | C7: 400000 | D7: =C7/Revenue!$A$23 -> 3636.3636 | E7: 6 | F7: 9 | G7: =F7-E7+1 -> 4 | H7: =IF(AND(H$1>=$E7,H$1<=$F7),$C7/$G7,0) -> 0 | I7: =IF(AND(I$1>=$E7,I$1<=$F7),$C7/$G7,0) -> 0 | J7: =IF(AND(J$1>=$E7,J$1<=$F7),$C7/$G7,0) -> 0 | K7: =IF(AND(K$1>=$E7,K$1<=$F7),$C7/$G7,0) -> 0 | L7: =IF(AND(L$1>=$E7,L$1<=$F7),$C7/$G7,0) -> 0 | M7: =IF(AND(M$1>=$E7,M$1<=$F7),$C7/$G7,0) -> 100000 | N7: =IF(AND(N$1>=$E7,N$1<=$F7),$C7/$G7,0) -> 100000 | O7: =IF(AND(O$1>=$E7,O$1<=$F7),$C7/$G7,0) -> 100000 | ... EI7: =IF(AND(EI$1>=$E7,EI$1<=$F7),$C7/$G7,0) -> 0
A8: =IF(ABS(SUM(H8:EI8)-C8)<0.0001,"OK","ERROR") -> OK | B8: Dog Park | C8: 30000 | D8: =C8/Revenue!$A$23 -> 272.72727 | E8: 10 | F8: 12 | G8: =F8-E8+1 -> 3 | H8: =IF(AND(H$1>=$E8,H$1<=$F8),$C8/$G8,0) -> 0 | I8: =IF(AND(I$1>=$E8,I$1<=$F8),$C8/$G8,0) -> 0 | J8: =IF(AND(J$1>=$E8,J$1<=$F8),$C8/$G8,0) -> 0 | K8: =IF(AND(K$1>=$E8,K$1<=$F8),$C8/$G8,0) -> 0 | L8: =IF(AND(L$1>=$E8,L$1<=$F8),$C8/$G8,0) -> 0 | M8: =IF(AND(M$1>=$E8,M$1<=$F8),$C8/$G8,0) -> 0 | N8: =IF(AND(N$1>=$E8,N$1<=$F8),$C8/$G8,0) -> 0 | O8: =IF(AND(O$1>=$E8,O$1<=$F8),$C8/$G8,0) -> 0 | ... EI8: =IF(AND(EI$1>=$E8,EI$1<=$F8),$C8/$G8,0) -> 0
A9: =IF(ABS(SUM(H9:EI9)-C9)<0.0001,"OK","ERROR") -> OK | B9: Other | C9: 0 | D9: =C9/Revenue!$A$23 -> 0 | E9: 1 | F9: 1 | G9: =F9-E9+1 -> 1 | H9: =IF(AND(H$1>=$E9,H$1<=$F9),$C9/$G9,0) -> 0 | I9: =IF(AND(I$1>=$E9,I$1<=$F9),$C9/$G9,0) -> 0 | J9: =IF(AND(J$1>=$E9,J$1<=$F9),$C9/$G9,0) -> 0 | K9: =IF(AND(K$1>=$E9,K$1<=$F9),$C9/$G9,0) -> 0 | L9: =IF(AND(L$1>=$E9,L$1<=$F9),$C9/$G9,0) -> 0 | M9: =IF(AND(M$1>=$E9,M$1<=$F9),$C9/$G9,0) -> 0 | N9: =IF(AND(N$1>=$E9,N$1<=$F9),$C9/$G9,0) -> 0 | O9: =IF(AND(O$1>=$E9,O$1<=$F9),$C9/$G9,0) -> 0 | ... EI9: =IF(AND(EI$1>=$E9,EI$1<=$F9),$C9/$G9,0) -> 0
A10: =IF(ABS(SUM(H10:EI10)-C10)<0.0001,"OK","ERROR") -> OK | B10: Other | C10: 0 | D10: =C10/Revenue!$A$23 -> 0 | E10: 1 | F10: 1 | G10: =F10-E10+1 -> 1 | H10: =IF(AND(H$1>=$E10,H$1<=$F10),$C10/$G10,0) -> 0 | I10: =IF(AND(I$1>=$E10,I$1<=$F10),$C10/$G10,0) -> 0 | J10: =IF(AND(J$1>=$E10,J$1<=$F10),$C10/$G10,0) -> 0 | K10: =IF(AND(K$1>=$E10,K$1<=$F10),$C10/$G10,0) -> 0 | L10: =IF(AND(L$1>=$E10,L$1<=$F10),$C10/$G10,0) -> 0 | M10: =IF(AND(M$1>=$E10,M$1<=$F10),$C10/$G10,0) -> 0 | N10: =IF(AND(N$1>=$E10,N$1<=$F10),$C10/$G10,0) -> 0 | O10: =IF(AND(O$1>=$E10,O$1<=$F10),$C10/$G10,0) -> 0 | ... EI10: =IF(AND(EI$1>=$E10,EI$1<=$F10),$C10/$G10,0) -> 0
A11: =IF(ABS(SUM(H11:EI11)-C11)<0.0001,"OK","ERROR") -> OK | B11: Other | C11: 0 | D11: =C11/Revenue!$A$23 -> 0 | E11: 1 | F11: 1 | G11: =F11-E11+1 -> 1 | H11: =IF(AND(H$1>=$E11,H$1<=$F11),$C11/$G11,0) -> 0 | I11: =IF(AND(I$1>=$E11,I$1<=$F11),$C11/$G11,0) -> 0 | J11: =IF(AND(J$1>=$E11,J$1<=$F11),$C11/$G11,0) -> 0 | K11: =IF(AND(K$1>=$E11,K$1<=$F11),$C11/$G11,0) -> 0 | L11: =IF(AND(L$1>=$E11,L$1<=$F11),$C11/$G11,0) -> 0 | M11: =IF(AND(M$1>=$E11,M$1<=$F11),$C11/$G11,0) -> 0 | N11: =IF(AND(N$1>=$E11,N$1<=$F11),$C11/$G11,0) -> 0 | O11: =IF(AND(O$1>=$E11,O$1<=$F11),$C11/$G11,0) -> 0 | ... EI11: =IF(AND(EI$1>=$E11,EI$1<=$F11),$C11/$G11,0) -> 0
A12: =IF(ABS(SUM(H12:EI12)-C12)<0.0001,"OK","ERROR") -> OK | B12: Other | C12: 0 | D12: =C12/Revenue!$A$23 -> 0 | E12: 1 | F12: 1 | G12: =F12-E12+1 -> 1 | H12: =IF(AND(H$1>=$E12,H$1<=$F12),$C12/$G12,0) -> 0 | I12: =IF(AND(I$1>=$E12,I$1<=$F12),$C12/$G12,0) -> 0 | J12: =IF(AND(J$1>=$E12,J$1<=$F12),$C12/$G12,0) -> 0 | K12: =IF(AND(K$1>=$E12,K$1<=$F12),$C12/$G12,0) -> 0 | L12: =IF(AND(L$1>=$E12,L$1<=$F12),$C12/$G12,0) -> 0 | M12: =IF(AND(M$1>=$E12,M$1<=$F12),$C12/$G12,0) -> 0 | N12: =IF(AND(N$1>=$E12,N$1<=$F12),$C12/$G12,0) -> 0 | O12: =IF(AND(O$1>=$E12,O$1<=$F12),$C12/$G12,0) -> 0 | ... EI12: =IF(AND(EI$1>=$E12,EI$1<=$F12),$C12/$G12,0) -> 0
A13: =IF(ABS(SUM(H13:EI13)-C13)<0.0001,"OK","ERROR") -> OK | B13: Other | C13: 0 | D13: =C13/Revenue!$A$23 -> 0 | E13: 1 | F13: 1 | G13: =F13-E13+1 -> 1 | H13: =IF(AND(H$1>=$E13,H$1<=$F13),$C13/$G13,0) -> 0 | I13: =IF(AND(I$1>=$E13,I$1<=$F13),$C13/$G13,0) -> 0 | J13: =IF(AND(J$1>=$E13,J$1<=$F13),$C13/$G13,0) -> 0 | K13: =IF(AND(K$1>=$E13,K$1<=$F13),$C13/$G13,0) -> 0 | L13: =IF(AND(L$1>=$E13,L$1<=$F13),$C13/$G13,0) -> 0 | M13: =IF(AND(M$1>=$E13,M$1<=$F13),$C13/$G13,0) -> 0 | N13: =IF(AND(N$1>=$E13,N$1<=$F13),$C13/$G13,0) -> 0 | O13: =IF(AND(O$1>=$E13,O$1<=$F13),$C13/$G13,0) -> 0 | ... EI13: =IF(AND(EI$1>=$E13,EI$1<=$F13),$C13/$G13,0) -> 0
A14: =IF(ABS(SUM(H14:EI14)-C14)<0.0001,"OK","ERROR") -> OK | B14: Other | C14: 0 | D14: =C14/Revenue!$A$23 -> 0 | E14: 1 | F14: 1 | G14: =F14-E14+1 -> 1 | H14: =IF(AND(H$1>=$E14,H$1<=$F14),$C14/$G14,0) -> 0 | I14: =IF(AND(I$1>=$E14,I$1<=$F14),$C14/$G14,0) -> 0 | J14: =IF(AND(J$1>=$E14,J$1<=$F14),$C14/$G14,0) -> 0 | K14: =IF(AND(K$1>=$E14,K$1<=$F14),$C14/$G14,0) -> 0 | L14: =IF(AND(L$1>=$E14,L$1<=$F14),$C14/$G14,0) -> 0 | M14: =IF(AND(M$1>=$E14,M$1<=$F14),$C14/$G14,0) -> 0 | N14: =IF(AND(N$1>=$E14,N$1<=$F14),$C14/$G14,0) -> 0 | O14: =IF(AND(O$1>=$E14,O$1<=$F14),$C14/$G14,0) -> 0 | ... EI14: =IF(AND(EI$1>=$E14,EI$1<=$F14),$C14/$G14,0) -> 0
A15: =IF(ABS(SUM(H15:EI15)-C15)<0.0001,"OK","ERROR") -> OK | B15: Other | C15: 0 | D15: =C15/Revenue!$A$23 -> 0 | E15: 1 | F15: 1 | G15: =F15-E15+1 -> 1 | H15: =IF(AND(H$1>=$E15,H$1<=$F15),$C15/$G15,0) -> 0 | I15: =IF(AND(I$1>=$E15,I$1<=$F15),$C15/$G15,0) -> 0 | J15: =IF(AND(J$1>=$E15,J$1<=$F15),$C15/$G15,0) -> 0 | K15: =IF(AND(K$1>=$E15,K$1<=$F15),$C15/$G15,0) -> 0 | L15: =IF(AND(L$1>=$E15,L$1<=$F15),$C15/$G15,0) -> 0 | M15: =IF(AND(M$1>=$E15,M$1<=$F15),$C15/$G15,0) -> 0 | N15: =IF(AND(N$1>=$E15,N$1<=$F15),$C15/$G15,0) -> 0 | O15: =IF(AND(O$1>=$E15,O$1<=$F15),$C15/$G15,0) -> 0 | ... EI15: =IF(AND(EI$1>=$E15,EI$1<=$F15),$C15/$G15,0) -> 0
A16: =IF(ABS(SUM(H16:EI16)-C16)<0.0001,"OK","ERROR") -> OK | B16: Other | C16: 0 | D16: =C16/Revenue!$A$23 -> 0 | E16: 1 | F16: 1 | G16: =F16-E16+1 -> 1 | H16: =IF(AND(H$1>=$E16,H$1<=$F16),$C16/$G16,0) -> 0 | I16: =IF(AND(I$1>=$E16,I$1<=$F16),$C16/$G16,0) -> 0 | J16: =IF(AND(J$1>=$E16,J$1<=$F16),$C16/$G16,0) -> 0 | K16: =IF(AND(K$1>=$E16,K$1<=$F16),$C16/$G16,0) -> 0 | L16: =IF(AND(L$1>=$E16,L$1<=$F16),$C16/$G16,0) -> 0 | M16: =IF(AND(M$1>=$E16,M$1<=$F16),$C16/$G16,0) -> 0 | N16: =IF(AND(N$1>=$E16,N$1<=$F16),$C16/$G16,0) -> 0 | O16: =IF(AND(O$1>=$E16,O$1<=$F16),$C16/$G16,0) -> 0 | ... EI16: =IF(AND(EI$1>=$E16,EI$1<=$F16),$C16/$G16,0) -> 0
... A20: =IF(ABS(SUM(H20:EI20)-C20)<0.0001,"OK","ERROR") -> OK | B20: Other | C20: 0 | D20: =C20/Revenue!$A$23 -> 0 | E20: 1 | F20: 1 | G20: =F20-E20+1 -> 1 | H20: =IF(AND(H$1>=$E20,H$1<=$F20),$C20/$G20,0) -> 0 | I20: =IF(AND(I$1>=$E20,I$1<=$F20),$C20/$G20,0) -> 0 | J20: =IF(AND(J$1>=$E20,J$1<=$F20),$C20/$G20,0) -> 0 | K20: =IF(AND(K$1>=$E20,K$1<=$F20),$C20/$G20,0) -> 0 | L20: =IF(AND(L$1>=$E20,L$1<=$F20),$C20/$G20,0) -> 0 | M20: =IF(AND(M$1>=$E20,M$1<=$F20),$C20/$G20,0) -> 0 | N20: =IF(AND(N$1>=$E20,N$1<=$F20),$C20/$G20,0) -> 0 | O20: =IF(AND(O$1>=$E20,O$1<=$F20),$C20/$G20,0) -> 0 | ... EI20: =IF(AND(EI$1>=$E20,EI$1<=$F20),$C20/$G20,0) -> 0
A21: =IF(ABS(SUM(H21:EI21)-C21)<0.0001,"OK","ERROR") -> OK | B21: Subtotal | C21: =SUM(C5:C20) -> 1180000 | D21: =SUM(D5:D20) -> 10727.273 | E21: {=MIN(IF($C$5:$C$20>0,E5:E20))} -> 2 | F21: {=MAX(IF($C$5:$C$20>0,F5:F20))} -> 12 | G21: =F21-E21+1 -> 11 | H21: =SUM(H5:H20) -> 0 | I21: =SUM(I5:I20) -> 125000 | J21: =SUM(J5:J20) -> 175000 | K21: =SUM(K5:K20) -> 175000 | L21: =SUM(L5:L20) -> 175000 | M21: =SUM(M5:M20) -> 150000 | N21: =SUM(N5:N20) -> 150000 | O21: =SUM(O5:O20) -> 100000 | ... EI21: =SUM(EI5:EI20) -> 0
B23: Interior Renovation Budget | EI23: 0
A24: Check | B24: Item | C24: Total | D24: Per Unit | E24: Month Start | F24: Month End | G24: Total Months
A25: =IF(ABS(SUM(H25:EI25)-C25)<0.0001,"OK","ERROR") -> OK | B25: Countertops | C25: =D25*Revenue!$A$23 -> 220000 | D25: 2000 | E25: 2 | F25: 25 | G25: =F25-E25+1 -> 24 | H25: =IF(AND(H$1>=$E25,H$1<=$F25),$C25/$G25,0) -> 0 | I25: =IF(AND(I$1>=$E25,I$1<=$F25),$C25/$G25,0) -> 9166.6667 | J25: =IF(AND(J$1>=$E25,J$1<=$F25),$C25/$G25,0) -> 9166.6667 | K25: =IF(AND(K$1>=$E25,K$1<=$F25),$C25/$G25,0) -> 9166.6667 | L25: =IF(AND(L$1>=$E25,L$1<=$F25),$C25/$G25,0) -> 9166.6667 | M25: =IF(AND(M$1>=$E25,M$1<=$F25),$C25/$G25,0) -> 9166.6667 | N25: =IF(AND(N$1>=$E25,N$1<=$F25),$C25/$G25,0) -> 9166.6667 | O25: =IF(AND(O$1>=$E25,O$1<=$F25),$C25/$G25,0) -> 9166.6667 | ... EI25: =IF(AND(EI$1>=$E25,EI$1<=$F25),$C25/$G25,0) -> 0
A26: =IF(ABS(SUM(H26:EI26)-C26)<0.0001,"OK","ERROR") -> OK | B26: Flooring | C26: =D26*Revenue!$A$23 -> 165000 | D26: 1500 | E26: 2 | F26: 25 | G26: =F26-E26+1 -> 24 | H26: =IF(AND(H$1>=$E26,H$1<=$F26),$C26/$G26,0) -> 0 | I26: =IF(AND(I$1>=$E26,I$1<=$F26),$C26/$G26,0) -> 6875 | J26: =IF(AND(J$1>=$E26,J$1<=$F26),$C26/$G26,0) -> 6875 | K26: =IF(AND(K$1>=$E26,K$1<=$F26),$C26/$G26,0) -> 6875 | L26: =IF(AND(L$1>=$E26,L$1<=$F26),$C26/$G26,0) -> 6875 | M26: =IF(AND(M$1>=$E26,M$1<=$F26),$C26/$G26,0) -> 6875 | N26: =IF(AND(N$1>=$E26,N$1<=$F26),$C26/$G26,0) -> 6875 | O26: =IF(AND(O$1>=$E26,O$1<=$F26),$C26/$G26,0) -> 6875 | ... EI26: =IF(AND(EI$1>=$E26,EI$1<=$F26),$C26/$G26,0) -> 0
A27: =IF(ABS(SUM(H27:EI27)-C27)<0.0001,"OK","ERROR") -> OK | B27: Cabinets | C27: =D27*Revenue!$A$23 -> 165000 | D27: 1500 | E27: 2 | F27: 25 | G27: =F27-E27+1 -> 24 | H27: =IF(AND(H$1>=$E27,H$1<=$F27),$C27/$G27,0) -> 0 | I27: =IF(AND(I$1>=$E27,I$1<=$F27),$C27/$G27,0) -> 6875 | J27: =IF(AND(J$1>=$E27,J$1<=$F27),$C27/$G27,0) -> 6875 | K27: =IF(AND(K$1>=$E27,K$1<=$F27),$C27/$G27,0) -> 6875 | L27: =IF(AND(L$1>=$E27,L$1<=$F27),$C27/$G27,0) -> 6875 | M27: =IF(AND(M$1>=$E27,M$1<=$F27),$C27/$G27,0) -> 6875 | N27: =IF(AND(N$1>=$E27,N$1<=$F27),$C27/$G27,0) -> 6875 | O27: =IF(AND(O$1>=$E27,O$1<=$F27),$C27/$G27,0) -> 6875 | ... EI27: =IF(AND(EI$1>=$E27,EI$1<=$F27),$C27/$G27,0) -> 0
A28: =IF(ABS(SUM(H28:EI28)-C28)<0.0001,"OK","ERROR") -> OK | B28: Fixtures | C28: =D28*Revenue!$A$23 -> 55000 | D28: 500 | E28: 2 | F28: 25 | G28: =F28-E28+1 -> 24 | H28: =IF(AND(H$1>=$E28,H$1<=$F28),$C28/$G28,0) -> 0 | I28: =IF(AND(I$1>=$E28,I$1<=$F28),$C28/$G28,0) -> 2291.6667 | J28: =IF(AND(J$1>=$E28,J$1<=$F28),$C28/$G28,0) -> 2291.6667 | K28: =IF(AND(K$1>=$E28,K$1<=$F28),$C28/$G28,0) -> 2291.6667 | L28: =IF(AND(L$1>=$E28,L$1<=$F28),$C28/$G28,0) -> 2291.6667 | M28: =IF(AND(M$1>=$E28,M$1<=$F28),$C28/$G28,0) -> 2291.6667 | N28: =IF(AND(N$1>=$E28,N$1<=$F28),$C28/$G28,0) -> 2291.6667 | O28: =IF(AND(O$1>=$E28,O$1<=$F28),$C28/$G28,0) -> 2291.6667 | ... EI28: =IF(AND(EI$1>=$E28,EI$1<=$F28),$C28/$G28,0) -> 0
A29: =IF(ABS(SUM(H29:EI29)-C29)<0.0001,"OK","ERROR") -> OK | B29: Other | C29: =D29*Revenue!$A$23 -> 0 | D29: 0 | E29: 1 | F29: 1 | G29: =F29-E29+1 -> 1 | H29: =IF(AND(H$1>=$E29,H$1<=$F29),$C29/$G29,0) -> 0 | I29: =IF(AND(I$1>=$E29,I$1<=$F29),$C29/$G29,0) -> 0 | J29: =IF(AND(J$1>=$E29,J$1<=$F29),$C29/$G29,0) -> 0 | K29: =IF(AND(K$1>=$E29,K$1<=$F29),$C29/$G29,0) -> 0 | L29: =IF(AND(L$1>=$E29,L$1<=$F29),$C29/$G29,0) -> 0 | M29: =IF(AND(M$1>=$E29,M$1<=$F29),$C29/$G29,0) -> 0 | N29: =IF(AND(N$1>=$E29,N$1<=$F29),$C29/$G29,0) -> 0 | O29: =IF(AND(O$1>=$E29,O$1<=$F29),$C29/$G29,0) -> 0 | ... EI29: =IF(AND(EI$1>=$E29,EI$1<=$F29),$C29/$G29,0) -> 0
A30: =IF(ABS(SUM(H30:EI30)-C30)<0.0001,"OK","ERROR") -> OK | B30: Other | C30: =D30*Revenue!$A$23 -> 0 | D30: 0 | E30: 1 | F30: 1 | G30: =F30-E30+1 -> 1 | H30: =IF(AND(H$1>=$E30,H$1<=$F30),$C30/$G30,0) -> 0 | I30: =IF(AND(I$1>=$E30,I$1<=$F30),$C30/$G30,0) -> 0 | J30: =IF(AND(J$1>=$E30,J$1<=$F30),$C30/$G30,0) -> 0 | K30: =IF(AND(K$1>=$E30,K$1<=$F30),$C30/$G30,0) -> 0 | L30: =IF(AND(L$1>=$E30,L$1<=$F30),$C30/$G30,0) -> 0 | M30: =IF(AND(M$1>=$E30,M$1<=$F30),$C30/$G30,0) -> 0 | N30: =IF(AND(N$1>=$E30,N$1<=$F30),$C30/$G30,0) -> 0 | O30: =IF(AND(O$1>=$E30,O$1<=$F30),$C30/$G30,0) -> 0 | ... EI30: =IF(AND(EI$1>=$E30,EI$1<=$F30),$C30/$G30,0) -> 0
A31: =IF(ABS(SUM(H31:EI31)-C31)<0.0001,"OK","ERROR") -> OK | B31: Other | C31: =D31*Revenue!$A$23 -> 0 | D31: 0 | E31: 1 | F31: 1 | G31: =F31-E31+1 -> 1 | H31: =IF(AND(H$1>=$E31,H$1<=$F31),$C31/$G31,0) -> 0 | I31: =IF(AND(I$1>=$E31,I$1<=$F31),$C31/$G31,0) -> 0 | J31: =IF(AND(J$1>=$E31,J$1<=$F31),$C31/$G31,0) -> 0 | K31: =IF(AND(K$1>=$E31,K$1<=$F31),$C31/$G31,0) -> 0 | L31: =IF(AND(L$1>=$E31,L$1<=$F31),$C31/$G31,0) -> 0 | M31: =IF(AND(M$1>=$E31,M$1<=$F31),$C31/$G31,0) -> 0 | N31: =IF(AND(N$1>=$E31,N$1<=$F31),$C31/$G31,0) -> 0 | O31: =IF(AND(O$1>=$E31,O$1<=$F31),$C31/$G31,0) -> 0 | ... EI31: =IF(AND(EI$1>=$E31,EI$1<=$F31),$C31/$G31,0) -> 0
A32: =IF(ABS(SUM(H32:EI32)-C32)<0.0001,"OK","ERROR") -> OK | B32: Other | C32: =D32*Revenue!$A$23 -> 0 | D32: 0 | E32: 1 | F32: 1 | G32: =F32-E32+1 -> 1 | H32: =IF(AND(H$1>=$E32,H$1<=$F32),$C32/$G32,0) -> 0 | I32: =IF(AND(I$1>=$E32,I$1<=$F32),$C32/$G32,0) -> 0 | J32: =IF(AND(J$1>=$E32,J$1<=$F32),$C32/$G32,0) -> 0 | K32: =IF(AND(K$1>=$E32,K$1<=$F32),$C32/$G32,0) -> 0 | L32: =IF(AND(L$1>=$E32,L$1<=$F32),$C32/$G32,0) -> 0 | M32: =IF(AND(M$1>=$E32,M$1<=$F32),$C32/$G32,0) -> 0 | N32: =IF(AND(N$1>=$E32,N$1<=$F32),$C32/$G32,0) -> 0 | O32: =IF(AND(O$1>=$E32,O$1<=$F32),$C32/$G32,0) -> 0 | ... EI32: =IF(AND(EI$1>=$E32,EI$1<=$F32),$C32/$G32,0) -> 0
A33: =IF(ABS(SUM(H33:EI33)-C33)<0.0001,"OK","ERROR") -> OK | B33: Other | C33: =D33*Revenue!$A$23 -> 0 | D33: 0 | E33: 1 | F33: 1 | G33: =F33-E33+1 -> 1 | H33: =IF(AND(H$1>=$E33,H$1<=$F33),$C33/$G33,0) -> 0 | I33: =IF(AND(I$1>=$E33,I$1<=$F33),$C33/$G33,0) -> 0 | J33: =IF(AND(J$1>=$E33,J$1<=$F33),$C33/$G33,0) -> 0 | K33: =IF(AND(K$1>=$E33,K$1<=$F33),$C33/$G33,0) -> 0 | L33: =IF(AND(L$1>=$E33,L$1<=$F33),$C33/$G33,0) -> 0 | M33: =IF(AND(M$1>=$E33,M$1<=$F33),$C33/$G33,0) -> 0 | N33: =IF(AND(N$1>=$E33,N$1<=$F33),$C33/$G33,0) -> 0 | O33: =IF(AND(O$1>=$E33,O$1<=$F33),$C33/$G33,0) -> 0 | ... EI33: =IF(AND(EI$1>=$E33,EI$1<=$F33),$C33/$G33,0) -> 0
A34: =IF(ABS(SUM(H34:EI34)-C34)<0.0001,"OK","ERROR") -> OK | B34: Other | C34: =D34*Revenue!$A$23 -> 0 | D34: 0 | E34: 1 | F34: 1 | G34: =F34-E34+1 -> 1 | H34: =IF(AND(H$1>=$E34,H$1<=$F34),$C34/$G34,0) -> 0 | I34: =IF(AND(I$1>=$E34,I$1<=$F34),$C34/$G34,0) -> 0 | J34: =IF(AND(J$1>=$E34,J$1<=$F34),$C34/$G34,0) -> 0 | K34: =IF(AND(K$1>=$E34,K$1<=$F34),$C34/$G34,0) -> 0 | L34: =IF(AND(L$1>=$E34,L$1<=$F34),$C34/$G34,0) -> 0 | M34: =IF(AND(M$1>=$E34,M$1<=$F34),$C34/$G34,0) -> 0 | N34: =IF(AND(N$1>=$E34,N$1<=$F34),$C34/$G34,0) -> 0 | O34: =IF(AND(O$1>=$E34,O$1<=$F34),$C34/$G34,0) -> 0 | ... EI34: =IF(AND(EI$1>=$E34,EI$1<=$F34),$C34/$G34,0) -> 0
A35: =IF(ABS(SUM(H35:EI35)-C35)<0.0001,"OK","ERROR") -> OK | B35: Other | C35: =D35*Revenue!$A$23 -> 0 | D35: 0 | E35: 1 | F35: 1 | G35: =F35-E35+1 -> 1 | H35: =IF(AND(H$1>=$E35,H$1<=$F35),$C35/$G35,0) -> 0 | I35: =IF(AND(I$1>=$E35,I$1<=$F35),$C35/$G35,0) -> 0 | J35: =IF(AND(J$1>=$E35,J$1<=$F35),$C35/$G35,0) -> 0 | K35: =IF(AND(K$1>=$E35,K$1<=$F35),$C35/$G35,0) -> 0 | L35: =IF(AND(L$1>=$E35,L$1<=$F35),$C35/$G35,0) -> 0 | M35: =IF(AND(M$1>=$E35,M$1<=$F35),$C35/$G35,0) -> 0 | N35: =IF(AND(N$1>=$E35,N$1<=$F35),$C35/$G35,0) -> 0 | O35: =IF(AND(O$1>=$E35,O$1<=$F35),$C35/$G35,0) -> 0 | ... EI35: =IF(AND(EI$1>=$E35,EI$1<=$F35),$C35/$G35,0) -> 0
A36: =IF(ABS(SUM(H36:EI36)-C36)<0.0001,"OK","ERROR") -> OK | B36: Other | C36: =D36*Revenue!$A$23 -> 0 | D36: 0 | E36: 1 | F36: 1 | G36: =F36-E36+1 -> 1 | H36: =IF(AND(H$1>=$E36,H$1<=$F36),$C36/$G36,0) -> 0 | I36: =IF(AND(I$1>=$E36,I$1<=$F36),$C36/$G36,0) -> 0 | J36: =IF(AND(J$1>=$E36,J$1<=$F36),$C36/$G36,0) -> 0 | K36: =IF(AND(K$1>=$E36,K$1<=$F36),$C36/$G36,0) -> 0 | L36: =IF(AND(L$1>=$E36,L$1<=$F36),$C36/$G36,0) -> 0 | M36: =IF(AND(M$1>=$E36,M$1<=$F36),$C36/$G36,0) -> 0 | N36: =IF(AND(N$1>=$E36,N$1<=$F36),$C36/$G36,0) -> 0 | O36: =IF(AND(O$1>=$E36,O$1<=$F36),$C36/$G36,0) -> 0 | ... EI36: =IF(AND(EI$1>=$E36,EI$1<=$F36),$C36/$G36,0) -> 0
... A40: =IF(ABS(SUM(H40:EI40)-C40)<0.0001,"OK","ERROR") -> OK | B40: Other | C40: =D40*Revenue!$A$23 -> 0 | D40: 0 | E40: 1 | F40: 1 | G40: =F40-E40+1 -> 1 | H40: =IF(AND(H$1>=$E40,H$1<=$F40),$C40/$G40,0) -> 0 | I40: =IF(AND(I$1>=$E40,I$1<=$F40),$C40/$G40,0) -> 0 | J40: =IF(AND(J$1>=$E40,J$1<=$F40),$C40/$G40,0) -> 0 | K40: =IF(AND(K$1>=$E40,K$1<=$F40),$C40/$G40,0) -> 0 | L40: =IF(AND(L$1>=$E40,L$1<=$F40),$C40/$G40,0) -> 0 | M40: =IF(AND(M$1>=$E40,M$1<=$F40),$C40/$G40,0) -> 0 | N40: =IF(AND(N$1>=$E40,N$1<=$F40),$C40/$G40,0) -> 0 | O40: =IF(AND(O$1>=$E40,O$1<=$F40),$C40/$G40,0) -> 0 | ... EI40: =IF(AND(EI$1>=$E40,EI$1<=$F40),$C40/$G40,0) -> 0
A41: =IF(ABS(SUM(H41:EI41)-C41)<0.0001,"OK","ERROR") -> OK | B41: Subtotal | C41: =SUM(C25:C40) -> 605000 | D41: =SUM(D25:D40) -> 5500 | E41: {=MIN(IF($C$25:$C$40>0,E25:E40))} -> 2 | F41: {=MAX(IF($C$25:$C$40>0,F25:F40))} -> 25 | G41: =F41-E41+1 -> 24 | H41: =SUM(H25:H40) -> 0 | I41: =SUM(I25:I40) -> 25208.333 | J41: =SUM(J25:J40) -> 25208.333 | K41: =SUM(K25:K40) -> 25208.333 | L41: =SUM(L25:L40) -> 25208.333 | M41: =SUM(M25:M40) -> 25208.333 | N41: =SUM(N25:N40) -> 25208.333 | O41: =SUM(O25:O40) -> 25208.333 | ... EI41: =SUM(EI25:EI40) -> 0
B43: Contingency | EI43: 0
A44: Check | B44: Percentage | C44: Total | D44: Per Unit | E44: Month Start | F44: Month End | G44: Total Months
A45: =IF(ABS(SUM(H45:EI45)-C45)<0.0001,"OK","ERROR") -> OK | B45: 0.1 | C45: =B45*SUM(C21,C41) -> 178500 | D45: =C45/Revenue!A23 -> 1622.7273 | E45: =MIN(E21,E41) -> 2 | F45: =MAX(F21,F41) -> 25 | G45: =F45-E45+1 -> 24 | H45: =$B$45*SUM(H21,H41) -> 0 | I45: =$B$45*SUM(I21,I41) -> 15020.833 | J45: =$B$45*SUM(J21,J41) -> 20020.833 | K45: =$B$45*SUM(K21,K41) -> 20020.833 | L45: =$B$45*SUM(L21,L41) -> 20020.833 | M45: =$B$45*SUM(M21,M41) -> 17520.833 | N45: =$B$45*SUM(N21,N41) -> 17520.833 | O45: =$B$45*SUM(O21,O41) -> 12520.833 | ... EI45: =$B$45*SUM(EI21,EI41) -> 0
B47: Overall Construction Budget | EI47: 0
A48: Check | B48: Item | C48: Total | D48: Per Unit | E48: Month Start | F48: Month End | G48: Total Months
A49: =IF(ABS(SUM(H49:EI49)-C49)<0.0001,"OK","ERROR") -> OK | B49: Total Construction Budget | C49: =SUM(C21,C41,C45) -> 1963500 | D49: =SUM(D21,D41,D45) -> 17850 | E49: =E45 -> 2 | F49: =F45 -> 25 | G49: =F49-E49+1 -> 24 | H49: =SUM(H21,H41,H45) -> 0 | I49: =SUM(I21,I41,I45) -> 165229.17 | J49: =SUM(J21,J41,J45) -> 220229.17 | K49: =SUM(K21,K41,K45) -> 220229.17 | L49: =SUM(L21,L41,L45) -> 220229.17 | M49: =SUM(M21,M41,M45) -> 192729.17 | N49: =SUM(N21,N41,N45) -> 192729.17 | O49: =SUM(O21,O41,O45) -> 137729.17 | ... EI49: =SUM(EI21,EI41,EI45) -> 0

Sheet Financing
A1: Check | B1: Acquisition Financing | ED1: 0
A2: =IF(ABS(A6-A8-A4)<0.0001,"OK","ERROR") -> OK | B2: Month | C2: 1 | D2: =C2+1 -> 2 | E2: =D2+1 -> 3 | F2: =E2+1 -> 4 | G2: =F2+1 -> 5 | H2: =G2+1 -> 6 | I2: =H2+1 -> 7 | J2: =I2+1 -> 8 | K2: =J2+1 -> 9 | ... ED2: =EC2+1 -> 132
B3: Date | C3: =EOMONTH(Summary!B25,1) -> 44255 | D3: =EOMONTH(C3,1) -> 44286 | E3: =EOMONTH(D3,1) -> 44316 | F3: =EOMONTH(E3,1) -> 44347 | G3: =EOMONTH(F3,1) -> 44377 | H3: =EOMONTH(G3,1) -> 44408 | I3: =EOMONTH(H3,1) -> 44439 | J3: =EOMONTH(I3,1) -> 44469 | K3: =EOMONTH(J3,1) -> 44500 | ... ED3: =EOMONTH(EC3,1) -> 48244
A4: =MAX(C4:ED4) -> 26000000 | B4: Starting Balance | C4: =Summary!E2 -> 26000000 | D4: =C9 -> 26000000 | E4: =D9 -> 26000000 | F4: =E9 -> 26000000 | G4: =F9 -> 26000000 | H4: =G9 -> 26000000 | I4: =H9 -> 26000000 | J4: =I9 -> 26000000 | K4: =J9 -> 26000000 | ... ED4: =EC9 -> 0
A5: =SUM(C5:ED5) -> 6099071.4 | B5: Total Loan Payment | C5: =IF(C2>MIN(Summary!$E$10,Summary!$K$19),0,IF(C2<=Summary!$E$7,Summary!$E$6/12*Financing!C4,PMT(Summary!$E$6/12,Summary!$E$9,-Summary!$E$2,0,0))) -> 86666.667 | D5: =IF(D2>MIN(Summary!$E$10,Summary!$K$19),0,IF(D2<=Summary!$E$7,Summary!$E$6/12*Financing!D4,PMT(Summary!$E$6/12,Summary!$E$9,-Summary!$E$2,0,0))) -> 86666.667 | E5: =IF(E2>MIN(Summary!$E$10,Summary!$K$19),0,IF(E2<=Summary!$E$7,Summary!$E$6/12*Financing!E4,PMT(Summary!$E$6/12,Summary!$E$9,-Summary!$E$2,0,0))) -> 86666.667 | F5: =IF(F2>MIN(Summary!$E$10,Summary!$K$19),0,IF(F2<=Summary!$E$7,Summary!$E$6/12*Financing!F4,PMT(Summary!$E$6/12,Summary!$E$9,-Summary!$E$2,0,0))) -> 86666.667 | G5: =IF(G2>MIN(Summary!$E$10,Summary!$K$19),0,IF(G2<=Summary!$E$7,Summary!$E$6/12*Financing!G4,PMT(Summary!$E$6/12,Summary!$E$9,-Summary!$E$2,0,0))) -> 86666.667 | H5: =IF(H2>MIN(Summary!$E$10,Summary!$K$19),0,IF(H2<=Summary!$E$7,Summary!$E$6/12*Financing!H4,PMT(Summary!$E$6/12,Summary!$E$9,-Summary!$E$2,0,0))) -> 86666.667 | I5: =IF(I2>MIN(Summary!$E$10,Summary!$K$19),0,IF(I2<=Summary!$E$7,Summary!$E$6/12*Financing!I4,PMT(Summary!$E$6/12,Summary!$E$9,-Summary!$E$2,0,0))) -> 86666.667 | J5: =IF(J2>MIN(Summary!$E$10,Summary!$K$19),0,IF(J2<=Summary!$E$7,Summary!$E$6/12*Financing!J4,PMT(Summary!$E$6/12,Summary!$E$9,-Summary!$E$2,0,0))) -> 86666.667 | ... ED5: =IF(ED2>MIN(Summary!$E$10,Summary!$K$19),0,IF(ED2<=Summary!$E$7,Summary!$E$6/12*Financing!ED4,PMT(Summary!$E$6/12,Summary!$E$9,-Summary!$E$2,0,0))) -> 0
A6: =SUM(C6:ED6) -> 934393.25 | B6: Principal Payment | C6: =C5-C7 -> 0 | D6: =D5-D7 -> 0 | E6: =E5-E7 -> 0 | F6: =F5-F7 -> 0 | G6: =G5-G7 -> 0 | H6: =H5-H7 -> 0 | I6: =I5-I7 -> 0 | J6: =J5-J7 -> 0 | ... ED6: =ED5-ED7 -> 0
A7: =SUM(C7:ED7) -> 5164678.2 | B7: Interest Payment | C7: =C4*Summary!$E$6/12 -> 86666.667 | D7: =D4*Summary!$E$6/12 -> 86666.667 | E7: =E4*Summary!$E$6/12 -> 86666.667 | F7: =F4*Summary!$E$6/12 -> 86666.667 | G7: =G4*Summary!$E$6/12 -> 86666.667 | H7: =H4*Summary!$E$6/12 -> 86666.667 | I7: =I4*Summary!$E$6/12 -> 86666.667 | J7: =J4*Summary!$E$6/12 -> 86666.667 | ... ED7: =ED4*Summary!$E$6/12 -> 0
A8: =SUM(C8:ED8) -> -25065607 | B8: Loan Payoff | C8: =IF(C2=MIN(Summary!$E$10,Summary!$K$19),-Financing!C4+Financing!C6,0) -> 0 | D8: =IF(D2=MIN(Summary!$E$10,Summary!$K$19),-Financing!D4+Financing!D6,0) -> 0 | E8: =IF(E2=MIN(Summary!$E$10,Summary!$K$19),-Financing!E4+Financing!E6,0) -> 0 | F8: =IF(F2=MIN(Summary!$E$10,Summary!$K$19),-Financing!F4+Financing!F6,0) -> 0 | G8: =IF(G2=MIN(Summary!$E$10,Summary!$K$19),-Financing!G4+Financing!G6,0) -> 0 | H8: =IF(H2=MIN(Summary!$E$10,Summary!$K$19),-Financing!H4+Financing!H6,0) -> 0 | I8: =IF(I2=MIN(Summary!$E$10,Summary!$K$19),-Financing!I4+Financing!I6,0) -> 0 | J8: =IF(J2=MIN(Summary!$E$10,Summary!$K$19),-Financing!J4+Financing!J6,0) -> 0 | ... ED8: =IF(ED2=MIN(Summary!$E$10,Summary!$K$19),-Financing!ED4+Financing!ED6,0) -> 0
B9: Ending Balance | C9: =C4-C6+C8 -> 26000000 | D9: =D4-D6+D8 -> 26000000 | E9: =E4-E6+E8 -> 26000000 | F9: =F4-F6+F8 -> 26000000 | G9: =G4-G6+G8 -> 26000000 | H9: =H4-H6+H8 -> 26000000 | I9: =I4-I6+I8 -> 26000000 | J9: =J4-J6+J8 -> 26000000 | ... ED9: =ED4-ED6+ED8 -> 0
A11: Check | B11: Refinancing | ED11: 0
A12: =IF(ABS(A16-A18-A14)<0.0001,"OK","ERROR") -> OK | B12: Month | C12: 1 | D12: =C12+1 -> 2 | E12: =D12+1 -> 3 | F12: =E12+1 -> 4 | G12: =F12+1 -> 5 | H12: =G12+1 -> 6 | I12: =H12+1 -> 7 | J12: =I12+1 -> 8 | K12: =J12+1 -> 9 | ... ED12: =EC12+1 -> 132
B13: Date | C13: =C3 -> 44255 | D13: =EOMONTH(C13,1) -> 44286 | E13: =EOMONTH(D13,1) -> 44316 | F13: =EOMONTH(E13,1) -> 44347 | G13: =EOMONTH(F13,1) -> 44377 | H13: =EOMONTH(G13,1) -> 44408 | I13: =EOMONTH(H13,1) -> 44439 | J13: =EOMONTH(I13,1) -> 44469 | K13: =EOMONTH(J13,1) -> 44500 | ... ED13: =EOMONTH(EC13,1) -> 48244
A14: =MAX(C14:ED14) -> 30000000 | B14: Starting Balance | C14: =IF(OR(C12>Summary!$K$19,Summary!$K$19=Summary!$E$10,C12<Summary!$E$10),0,IF(C12=Summary!$E$13,Summary!$E$14,Financing!B19)) -> 0 | D14: =IF(OR(D12>Summary!$K$19,Summary!$K$19=Summary!$E$10,D12<Summary!$E$10),0,IF(D12=Summary!$E$13,Summary!$E$14,Financing!C19)) -> 0 | E14: =IF(OR(E12>Summary!$K$19,Summary!$K$19=Summary!$E$10,E12<Summary!$E$10),0,IF(E12=Summary!$E$13,Summary!$E$14,Financing!D19)) -> 0 | F14: =IF(OR(F12>Summary!$K$19,Summary!$K$19=Summary!$E$10,F12<Summary!$E$10),0,IF(F12=Summary!$E$13,Summary!$E$14,Financing!E19)) -> 0 | G14: =IF(OR(G12>Summary!$K$19,Summary!$K$19=Summary!$E$10,G12<Summary!$E$10),0,IF(G12=Summary!$E$13,Summary!$E$14,Financing!F19)) -> 0 | H14: =IF(OR(H12>Summary!$K$19,Summary!$K$19=Summary!$E$10,H12<Summary!$E$10),0,IF(H12=Summary!$E$13,Summary!$E$14,Financing!G19)) -> 0 | I14: =IF(OR(I12>Summary!$K$19,Summary!$K$19=Summary!$E$10,I12<Summary!$E$10),0,IF(I12=Summary!$E$13,Summary!$E$14,Financing!H19)) -> 0 | J14: =IF(OR(J12>Summary!$K$19,Summary!$K$19=Summary!$E$10,J12<Summary!$E$10),0,IF(J12=Summary!$E$13,Summary!$E$14,Financing!I19)) -> 0 | ... ED14: =IF(OR(ED12>Summary!$K$19,Summary!$K$19=Summary!$E$10,ED12<Summary!$E$10),0,IF(ED12=Summary!$E$13,Summary!$E$14,Financing!EC19)) -> 0
A15: =SUM(C15:ED15) -> 7037390.1 | B15: Total Loan Payment | C15: =IF(OR(C12>Summary!$K$19,C12<=Summary!$E$13),0,IF(C12<=Summary!$E$13+Summary!$E$20,Summary!$E$19/12*Financing!C14,PMT(Summary!$E$19/12,Summary!$E$22,-Summary!$E$14,0,0))) -> 0 | D15: =IF(OR(D12>Summary!$K$19,D12<=Summary!$E$13),0,IF(D12<=Summary!$E$13+Summary!$E$20,Summary!$E$19/12*Financing!D14,PMT(Summary!$E$19/12,Summary!$E$22,-Summary!$E$14,0,0))) -> 0 | E15: =IF(OR(E12>Summary!$K$19,E12<=Summary!$E$13),0,IF(E12<=Summary!$E$13+Summary!$E$20,Summary!$E$19/12*Financing!E14,PMT(Summary!$E$19/12,Summary!$E$22,-Summary!$E$14,0,0))) -> 0 | F15: =IF(OR(F12>Summary!$K$19,F12<=Summary!$E$13),0,IF(F12<=Summary!$E$13+Summary!$E$20,Summary!$E$19/12*Financing!F14,PMT(Summary!$E$19/12,Summary!$E$22,-Summary!$E$14,0,0))) -> 0 | G15: =IF(OR(G12>Summary!$K$19,G12<=Summary!$E$13),0,IF(G12<=Summary!$E$13+Summary!$E$20,Summary!$E$19/12*Financing!G14,PMT(Summary!$E$19/12,Summary!$E$22,-Summary!$E$14,0,0))) -> 0 | H15: =IF(OR(H12>Summary!$K$19,H12<=Summary!$E$13),0,IF(H12<=Summary!$E$13+Summary!$E$20,Summary!$E$19/12*Financing!H14,PMT(Summary!$E$19/12,Summary!$E$22,-Summary!$E$14,0,0))) -> 0 | I15: =IF(OR(I12>Summary!$K$19,I12<=Summary!$E$13),0,IF(I12<=Summary!$E$13+Summary!$E$20,Summary!$E$19/12*Financing!I14,PMT(Summary!$E$19/12,Summary!$E$22,-Summary!$E$14,0,0))) -> 0 | J15: =IF(OR(J12>Summary!$K$19,J12<=Summary!$E$13),0,IF(J12<=Summary!$E$13+Summary!$E$20,Summary!$E$19/12*Financing!J14,PMT(Summary!$E$19/12,Summary!$E$22,-Summary!$E$14,0,0))) -> 0 | ... ED15: =IF(OR(ED12>Summary!$K$19,ED12<=Summary!$E$13),0,IF(ED12<=Summary!$E$13+Summary!$E$20,Summary!$E$19/12*Financing!ED14,PMT(Summary!$E$19/12,Summary!$E$22,-Summary!$E$14,0,0))) -> 0
A16: =SUM(C16:ED16) -> 1078146.1 | B16: Principal Payment | C16: =C15-C17 -> 0 | D16: =D15-D17 -> 0 | E16: =E15-E17 -> 0 | F16: =F15-F17 -> 0 | G16: =G15-G17 -> 0 | H16: =H15-H17 -> 0 | I16: =I15-I17 -> 0 | J16: =J15-J17 -> 0 | ... ED16: =ED15-ED17 -> 0
A17: =SUM(C17:ED17) -> 5959244.1 | B17: Interest Payment | C17: =IF(C12=Summary!$E$13,0,Summary!$E$19/12*Financing!C14) -> 0 | D17: =IF(D12=Summary!$E$13,0,Summary!$E$19/12*Financing!D14) -> 0 | E17: =IF(E12=Summary!$E$13,0,Summary!$E$19/12*Financing!E14) -> 0 | F17: =IF(F12=Summary!$E$13,0,Summary!$E$19/12*Financing!F14) -> 0 | G17: =IF(G12=Summary!$E$13,0,Summary!$E$19/12*Financing!G14) -> 0 | H17: =IF(H12=Summary!$E$13,0,Summary!$E$19/12*Financing!H14) -> 0 | I17: =IF(I12=Summary!$E$13,0,Summary!$E$19/12*Financing!I14) -> 0 | J17: =IF(J12=Summary!$E$13,0,Summary!$E$19/12*Financing!J14) -> 0 | ... ED17: =IF(ED12=Summary!$E$13,0,Summary!$E$19/12*Financing!ED14) -> 0
A18: =SUM(C18:ED18) -> -28921854 | B18: Loan Payoff | C18: =IF(C12=Summary!$K$19,-Financing!C14+Financing!C16,0) -> 0 | D18: =IF(D12=Summary!$K$19,-Financing!D14+Financing!D16,0) -> 0 | E18: =IF(E12=Summary!$K$19,-Financing!E14+Financing!E16,0) -> 0 | F18: =IF(F12=Summary!$K$19,-Financing!F14+Financing!F16,0) -> 0 | G18: =IF(G12=Summary!$K$19,-Financing!G14+Financing!G16,0) -> 0 | H18: =IF(H12=Summary!$K$19,-Financing!H14+Financing!H16,0) -> 0 | I18: =IF(I12=Summary!$K$19,-Financing!I14+Financing!I16,0) -> 0 | J18: =IF(J12=Summary!$K$19,-Financing!J14+Financing!J16,0) -> 0 | ... ED18: =IF(ED12=Summary!$K$19,-Financing!ED14+Financing!ED16,0) -> 0
B19: Ending Balance | C19: =C14-C16+C18 -> 0 | D19: =D14-D16+D18 -> 0 | E19: =E14-E16+E18 -> 0 | F19: =F14-F16+F18 -> 0 | G19: =G14-G16+G18 -> 0 | H19: =H14-H16+H18 -> 0 | I19: =I14-I16+I18 -> 0 | J19: =J14-J16+J18 -> 0 | ... ED19: =ED14-ED16+ED18 -> 0

Sheet Monthly CF
B1: Month | C1: 0 | D1: 1 | E1: =D1+1 -> 2 | F1: =E1+1 -> 3 | G1: =F1+1 -> 4 | H1: =G1+1 -> 5 | I1: =H1+1 -> 6 | J1: =I1+1 -> 7 | K1: =J1+1 -> 8 | L1: =K1+1 -> 9 | ... EE1: =ED1+1 -> 132
B2: Year | C2: 0 | D2: =ROUNDUP(D1/12,0) -> 1 | E2: =ROUNDUP(E1/12,0) -> 1 | F2: =ROUNDUP(F1/12,0) -> 1 | G2: =ROUNDUP(G1/12,0) -> 1 | H2: =ROUNDUP(H1/12,0) -> 1 | I2: =ROUNDUP(I1/12,0) -> 1 | J2: =ROUNDUP(J1/12,0) -> 1 | K2: =ROUNDUP(K1/12,0) -> 1 | ... EE2: =ROUNDUP(EE1/12,0) -> 11
B3: Month Ending | C3: =Summary!B25 -> 44227 | D3: =EOMONTH(C3,1) -> 44255 | E3: =EOMONTH(D3,1) -> 44286 | F3: =EOMONTH(E3,1) -> 44316 | G3: =EOMONTH(F3,1) -> 44347 | H3: =EOMONTH(G3,1) -> 44377 | I3: =EOMONTH(H3,1) -> 44408 | J3: =EOMONTH(I3,1) -> 44439 | K3: =EOMONTH(J3,1) -> 44469 | ... EE3: =EOMONTH(ED3,1) -> 48244
B5: Revenue
A6: =SUMIF($C$1:$EE$1,"<="&Summary!$K$19,'Monthly CF'!C6:EE6) -> 36563661 | B6: Gross Potential Rental Revenue | D6: =Revenue!AF5 -> 245000 | E6: =Revenue!AG5 -> 245998.16 | F6: =Revenue!AH5 -> 247000.39 | G6: =Revenue!AI5 -> 248006.7 | H6: =Revenue!AJ5 -> 250033.5 | I6: =Revenue!AK5 -> 252072.71 | J6: =Revenue!AL5 -> 254124.38 | K6: =Revenue!AM5 -> 256188.58 | ... EE6: =Revenue!FG5 -> 363854.59
A7: =SUMIF($C$1:$EE$1,"<="&Summary!$K$19,'Monthly CF'!C7:EE7) -> -1875029.6 | B7: Physical Vacancy | D7: =D$6*-HLOOKUP(D$2,Revenue!$S$1:$AC$5,MATCH('Monthly CF'!$B7,Revenue!$R$1:$R$5,0),0) -> -14700 | E7: =E$6*-HLOOKUP(E$2,Revenue!$S$1:$AC$5,MATCH('Monthly CF'!$B7,Revenue!$R$1:$R$5,0),0) -> -14759.89 | F7: =F$6*-HLOOKUP(F$2,Revenue!$S$1:$AC$5,MATCH('Monthly CF'!$B7,Revenue!$R$1:$R$5,0),0) -> -14820.023 | G7: =G$6*-HLOOKUP(G$2,Revenue!$S$1:$AC$5,MATCH('Monthly CF'!$B7,Revenue!$R$1:$R$5,0),0) -> -14880.402 | H7: =H$6*-HLOOKUP(H$2,Revenue!$S$1:$AC$5,MATCH('Monthly CF'!$B7,Revenue!$R$1:$R$5,0),0) -> -15002.01 | I7: =I$6*-HLOOKUP(I$2,Revenue!$S$1:$AC$5,MATCH('Monthly CF'!$B7,Revenue!$R$1:$R$5,0),0) -> -15124.363 | J7: =J$6*-HLOOKUP(J$2,Revenue!$S$1:$AC$5,MATCH('Monthly CF'!$B7,Revenue!$R$1:$R$5,0),0) -> -15247.463 | K7: =K$6*-HLOOKUP(K$2,Revenue!$S$1:$AC$5,MATCH('Monthly CF'!$B7,Revenue!$R$1:$R$5,0),0) -> -15371.315 | ... EE7: =EE$6*-HLOOKUP(EE$2,Revenue!$S$1:$AC$5,MATCH('Monthly CF'!$B7,Revenue!$R$1:$R$5,0),0) -> -18192.729
A8: =SUMIF($C$1:$EE$1,"<="&Summary!$K$19,'Monthly CF'!C8:EE8) -> -206241.58 | B8: Bad Debt | D8: =D$6*-HLOOKUP(D$2,Revenue!$S$1:$AC$5,MATCH('Monthly CF'!$B8,Revenue!$R$1:$R$5,0),0) -> -2450 | E8: =E$6*-HLOOKUP(E$2,Revenue!$S$1:$AC$5,MATCH('Monthly CF'!$B8,Revenue!$R$1:$R$5,0),0) -> -2459.9816 | F8: =F$6*-HLOOKUP(F$2,Revenue!$S$1:$AC$5,MATCH('Monthly CF'!$B8,Revenue!$R$1:$R$5,0),0) -> -2470.0039 | G8: =G$6*-HLOOKUP(G$2,Revenue!$S$1:$AC$5,MATCH('Monthly CF'!$B8,Revenue!$R$1:$R$5,0),0) -> -2480.067 | H8: =H$6*-HLOOKUP(H$2,Revenue!$S$1:$AC$5,MATCH('Monthly CF'!$B8,Revenue!$R$1:$R$5,0),0) -> -2500.335 | I8: =I$6*-HLOOKUP(I$2,Revenue!$S$1:$AC$5,MATCH('Monthly CF'!$B8,Revenue!$R$1:$R$5,0),0) -> -2520.7271 | J8: =J$6*-HLOOKUP(J$2,Revenue!$S$1:$AC$5,MATCH('Monthly CF'!$B8,Revenue!$R$1:$R$5,0),0) -> -2541.2438 | K8: =K$6*-HLOOKUP(K$2,Revenue!$S$1:$AC$5,MATCH('Monthly CF'!$B8,Revenue!$R$1:$R$5,0),0) -> -2561.8858 | ... EE8: =EE$6*-HLOOKUP(EE$2,Revenue!$S$1:$AC$5,MATCH('Monthly CF'!$B8,Revenue!$R$1:$R$5,0),0) -> -1819.2729
A9: =SUMIF($C$1:$EE$1,"<="&Summary!$K$19,'Monthly CF'!C9:EE9) -> -46846.558 | B9: Concessions | D9: =D$6*-HLOOKUP(D$2,Revenue!$S$1:$AC$5,MATCH('Monthly CF'!$B9,Revenue!$R$1:$R$5,0),0) -> -2450 | E9: =E$6*-HLOOKUP(E$2,Revenue!$S$1:$AC$5,MATCH('Monthly CF'!$B9,Revenue!$R$1:$R$5,0),0) -> -2459.9816 | F9: =F$6*-HLOOKUP(F$2,Revenue!$S$1:$AC$5,MATCH('Monthly CF'!$B9,Revenue!$R$1:$R$5,0),0) -> -2470.0039 | G9: =G$6*-HLOOKUP(G$2,Revenue!$S$1:$AC$5,MATCH('Monthly CF'!$B9,Revenue!$R$1:$R$5,0),0) -> -2480.067 | H9: =H$6*-HLOOKUP(H$2,Revenue!$S$1:$AC$5,MATCH('Monthly CF'!$B9,Revenue!$R$1:$R$5,0),0) -> -2500.335 | I9: =I$6*-HLOOKUP(I$2,Revenue!$S$1:$AC$5,MATCH('Monthly CF'!$B9,Revenue!$R$1:$R$5,0),0) -> -2520.7271 | J9: =J$6*-HLOOKUP(J$2,Revenue!$S$1:$AC$5,MATCH('Monthly CF'!$B9,Revenue!$R$1:$R$5,0),0) -> -2541.2438 | K9: =K$6*-HLOOKUP(K$2,Revenue!$S$1:$AC$5,MATCH('Monthly CF'!$B9,Revenue!$R$1:$R$5,0),0) -> -2561.8858 | ... EE9: =EE$6*-HLOOKUP(EE$2,Revenue!$S$1:$AC$5,MATCH('Monthly CF'!$B9,Revenue!$R$1:$R$5,0),0) -> 0
A10: =SUMIF($C$1:$EE$1,"<="&Summary!$K$19,'Monthly CF'!C10:EE10) -> 0 | B10: Other Loss | D10: =D$6*-HLOOKUP(D$2,Revenue!$S$1:$AC$5,MATCH('Monthly CF'!$B10,Revenue!$R$1:$R$5,0),0) -> 0 | E10: =E$6*-HLOOKUP(E$2,Revenue!$S$1:$AC$5,MATCH('Monthly CF'!$B10,Revenue!$R$1:$R$5,0),0) -> 0 | F10: =F$6*-HLOOKUP(F$2,Revenue!$S$1:$AC$5,MATCH('Monthly CF'!$B10,Revenue!$R$1:$R$5,0),0) -> 0 | G10: =G$6*-HLOOKUP(G$2,Revenue!$S$1:$AC$5,MATCH('Monthly CF'!$B10,Revenue!$R$1:$R$5,0),0) -> 0 | H10: =H$6*-HLOOKUP(H$2,Revenue!$S$1:$AC$5,MATCH('Monthly CF'!$B10,Revenue!$R$1:$R$5,0),0) -> 0 | I10: =I$6*-HLOOKUP(I$2,Revenue!$S$1:$AC$5,MATCH('Monthly CF'!$B10,Revenue!$R$1:$R$5,0),0) -> 0 | J10: =J$6*-HLOOKUP(J$2,Revenue!$S$1:$AC$5,MATCH('Monthly CF'!$B10,Revenue!$R$1:$R$5,0),0) -> 0 | K10: =K$6*-HLOOKUP(K$2,Revenue!$S$1:$AC$5,MATCH('Monthly CF'!$B10,Revenue!$R$1:$R$5,0),0) -> 0 | ... EE10: =EE$6*-HLOOKUP(EE$2,Revenue!$S$1:$AC$5,MATCH('Monthly CF'!$B10,Revenue!$R$1:$R$5,0),0) -> 0
A11: =SUMIF($C$1:$EE$1,"<="&Summary!$K$19,'Monthly CF'!C11:EE11) -> 34435543 | B11: Net Rental Income | D11: =SUM(D6:D10) -> 225400 | E11: =SUM(E6:E10) -> 226318.31 | F11: =SUM(F6:F10) -> 227240.36 | G11: =SUM(G6:G10) -> 228166.16 | H11: =SUM(H6:H10) -> 230030.82 | I11: =SUM(I6:I10) -> 231906.89 | J11: =SUM(J6:J10) -> 233794.43 | K11: =SUM(K6:K10) -> 235693.5 | ... EE11: =SUM(EE6:EE10) -> 343842.59
B13: Other Income
A14: =SUMIF($C$1:$EE$1,"<="&Summary!$K$19,'Monthly CF'!C14:EE14) -> 153392.8 | B14: =Revenue!O2 -> Laundry Income | D14: =IF(D$1=1,Revenue!$P2*Revenue!$A$23,'Monthly CF'!C14*((1+HLOOKUP('Monthly CF'!C$2,Revenue!$S$8:$AC$10,3,0))^(1/12))) -> 1100 | E14: =IF(E$1=1,Revenue!$P2*Revenue!$A$23,'Monthly CF'!D14*((1+HLOOKUP('Monthly CF'!D$2,Revenue!$S$8:$AC$10,3,0))^(1/12))) -> 1102.7129 | F14: =IF(F$1=1,Revenue!$P2*Revenue!$A$23,'Monthly CF'!E14*((1+HLOOKUP('Monthly CF'!E$2,Revenue!$S$8:$AC$10,3,0))^(1/12))) -> 1105.4325 | G14: =IF(G$1=1,Revenue!$P2*Revenue!$A$23,'Monthly CF'!F14*((1+HLOOKUP('Monthly CF'!F$2,Revenue!$S$8:$AC$10,3,0))^(1/12))) -> 1108.1588 | H14: =IF(H$1=1,Revenue!$P2*Revenue!$A$23,'Monthly CF'!G14*((1+HLOOKUP('Monthly CF'!G$2,Revenue!$S$8:$AC$10,3,0))^(1/12))) -> 1110.8918 | I14: =IF(I$1=1,Revenue!$P2*Revenue!$A$23,'Monthly CF'!H14*((1+HLOOKUP('Monthly CF'!H$2,Revenue!$S$8:$AC$10,3,0))^(1/12))) -> 1113.6316 | J14: =IF(J$1=1,Revenue!$P2*Revenue!$A$23,'Monthly CF'!I14*((1+HLOOKUP('Monthly CF'!I$2,Revenue!$S$8:$AC$10,3,0))^(1/12))) -> 1116.3781 | K14: =IF(K$1=1,Revenue!$P2*Revenue!$A$23,'Monthly CF'!J14*((1+HLOOKUP('Monthly CF'!J$2,Revenue!$S$8:$AC$10,3,0))^(1/12))) -> 1119.1314 | ... EE14: =IF(EE$1=1,Revenue!$P2*Revenue!$A$23,'Monthly CF'!ED14*((1+HLOOKUP('Monthly CF'!ED$2,Revenue!$S$8:$AC$10,3,0))^(1/12))) -> 1518.9112
A15: =SUMIF($C$1:$EE$1,"<="&Summary!$K$19,'Monthly CF'!C15:EE15) -> 153392.8 | B15: =Revenue!O3 -> Late Fees | D15: =IF(D$1=1,Revenue!$P3*Revenue!$A$23,'Monthly CF'!C15*((1+HLOOKUP('Monthly CF'!C$2,Revenue!$S$8:$AC$10,3,0))^(1/12))) -> 1100 | E15: =IF(E$1=1,Revenue!$P3*Revenue!$A$23,'Monthly CF'!D15*((1+HLOOKUP('Monthly CF'!D$2,Revenue!$S$8:$AC$10,3,0))^(1/12))) -> 1102.7129 | F15: =IF(F$1=1,Revenue!$P3*Revenue!$A$23,'Monthly CF'!E15*((1+HLOOKUP('Monthly CF'!E$2,Revenue!$S$8:$AC$10,3,0))^(1/12))) -> 1105.4325 | G15: =IF(G$1=1,Revenue!$P3*Revenue!$A$23,'Monthly CF'!F15*((1+HLOOKUP('Monthly CF'!F$2,Revenue!$S$8:$AC$10,3,0))^(1/12))) -> 1108.1588 | H15: =IF(H$1=1,Revenue!$P3*Revenue!$A$23,'Monthly CF'!G15*((1+HLOOKUP('Monthly CF'!G$2,Revenue!$S$8:$AC$10,3,0))^(1/12))) -> 1110.8918 | I15: =IF(I$1=1,Revenue!$P3*Revenue!$A$23,'Monthly CF'!H15*((1+HLOOKUP('Monthly CF'!H$2,Revenue!$S$8:$AC$10,3,0))^(1/12))) -> 1113.6316 | J15: =IF(J$1=1,Revenue!$P3*Revenue!$A$23,'Monthly CF'!I15*((1+HLOOKUP('Monthly CF'!I$2,Revenue!$S$8:$AC$10,3,0))^(1/12))) -> 1116.3781 | K15: =IF(K$1=1,Revenue!$P3*Revenue!$A$23,'Monthly CF'!J15*((1+HLOOKUP('Monthly CF'!J$2,Revenue!$S$8:$AC$10,3,0))^(1/12))) -> 1119.1314 | ... EE15: =IF(EE$1=1,Revenue!$P3*Revenue!$A$23,'Monthly CF'!ED15*((1+HLOOKUP('Monthly CF'!ED$2,Revenue!$S$8:$AC$10,3,0))^(1/12))) -> 1518.9112
A16: =SUMIF($C$1:$EE$1,"<="&Summary!$K$19,'Monthly CF'!C16:EE16) -> 383481.99 | B16: =Revenue!O4 -> Pet Rent | D16: =IF(D$1=1,Revenue!$P4*Revenue!$A$23,'Monthly CF'!C16*((1+HLOOKUP('Monthly CF'!C$2,Revenue!$S$8:$AC$10,3,0))^(1/12))) -> 2750 | E16: =IF(E$1=1,Revenue!$P4*Revenue!$A$23,'Monthly CF'!D16*((1+HLOOKUP('Monthly CF'!D$2,Revenue!$S$8:$AC$10,3,0))^(1/12))) -> 2756.7822 | F16: =IF(F$1=1,Revenue!$P4*Revenue!$A$23,'Monthly CF'!E16*((1+HLOOKUP('Monthly CF'!E$2,Revenue!$S$8:$AC$10,3,0))^(1/12))) -> 2763.5812 | G16: =IF(G$1=1,Revenue!$P4*Revenue!$A$23,'Monthly CF'!F16*((1+HLOOKUP('Monthly CF'!F$2,Revenue!$S$8:$AC$10,3,0))^(1/12))) -> 2770.3969 | H16: =IF(H$1=1,Revenue!$P4*Revenue!$A$23,'Monthly CF'!G16*((1+HLOOKUP('Monthly CF'!G$2,Revenue!$S$8:$AC$10,3,0))^(1/12))) -> 2777.2295 | I16: =IF(I$1=1,Revenue!$P4*Revenue!$A$23,'Monthly CF'!H16*((1+HLOOKUP('Monthly CF'!H$2,Revenue!$S$8:$AC$10,3,0))^(1/12))) -> 2784.0789 | J16: =IF(J$1=1,Revenue!$P4*Revenue!$A$23,'Monthly CF'!I16*((1+HLOOKUP('Monthly CF'!I$2,Revenue!$S$8:$AC$10,3,0))^(1/12))) -> 2790.9452 | K16: =IF(K$1=1,Revenue!$P4*Revenue!$A$23,'Monthly CF'!J16*((1+HLOOKUP('Monthly CF'!J$2,Revenue!$S$8:$AC$10,3,0))^(1/12))) -> 2797.8284 | ... EE16: =IF(EE$1=1,Revenue!$P4*Revenue!$A$23,'Monthly CF'!ED16*((1+HLOOKUP('Monthly CF'!ED$2,Revenue!$S$8:$AC$10,3,0))^(1/12))) -> 3797.278
A17: =SUMIF($C$1:$EE$1,"<="&Summary!$K$19,'Monthly CF'!C17:EE17) -> 76696.398 | B17: =Revenue!O5 -> Pet Fees | D17: =IF(D$1=1,Revenue!$P5*Revenue!$A$23,'Monthly CF'!C17*((1+HLOOKUP('Monthly CF'!C$2,Revenue!$S$8:$AC$10,3,0))^(1/12))) -> 550 | E17: =IF(E$1=1,Revenue!$P5*Revenue!$A$23,'Monthly CF'!D17*((1+HLOOKUP('Monthly CF'!D$2,Revenue!$S$8:$AC$10,3,0))^(1/12))) -> 551.35645 | F17: =IF(F$1=1,Revenue!$P5*Revenue!$A$23,'Monthly CF'!E17*((1+HLOOKUP('Monthly CF'!E$2,Revenue!$S$8:$AC$10,3,0))^(1/12))) -> 552.71624 | G17: =IF(G$1=1,Revenue!$P5*Revenue!$A$23,'Monthly CF'!F17*((1+HLOOKUP('Monthly CF'!F$2,Revenue!$S$8:$AC$10,3,0))^(1/12))) -> 554.07939 | H17: =IF(H$1=1,Revenue!$P5*Revenue!$A$23,'Monthly CF'!G17*((1+HLOOKUP('Monthly CF'!G$2,Revenue!$S$8:$AC$10,3,0))^(1/12))) -> 555.4459 | I17: =IF(I$1=1,Revenue!$P5*Revenue!$A$23,'Monthly CF'!H17*((1+HLOOKUP('Monthly CF'!H$2,Revenue!$S$8:$AC$10,3,0))^(1/12))) -> 556.81578 | J17: =IF(J$1=1,Revenue!$P5*Revenue!$A$23,'Monthly CF'!I17*((1+HLOOKUP('Monthly CF'!I$2,Revenue!$S$8:$AC$10,3,0))^(1/12))) -> 558.18904 | K17: =IF(K$1=1,Revenue!$P5*Revenue!$A$23,'Monthly CF'!J17*((1+HLOOKUP('Monthly CF'!J$2,Revenue!$S$8:$AC$10,3,0))^(1/12))) -> 559.56568 | ... EE17: =IF(EE$1=1,Revenue!$P5*Revenue!$A$23,'Monthly CF'!ED17*((1+HLOOKUP('Monthly CF'!ED$2,Revenue!$S$8:$AC$10,3,0))^(1/12))) -> 759.45561
A18: =SUMIF($C$1:$EE$1,"<="&Summary!$K$19,'Monthly CF'!C18:EE18) -> 0 | B18: =Revenue!O6 -> Garage Income | D18: =IF(D$1=1,Revenue!$P6*Revenue!$A$23,'Monthly CF'!C18*((1+HLOOKUP('Monthly CF'!C$2,Revenue!$S$8:$AC$10,3,0))^(1/12))) -> 0 | E18: =IF(E$1=1,Revenue!$P6*Revenue!$A$23,'Monthly CF'!D18*((1+HLOOKUP('Monthly CF'!D$2,Revenue!$S$8:$AC$10,3,0))^(1/12))) -> 0 | F18: =IF(F$1=1,Revenue!$P6*Revenue!$A$23,'Monthly CF'!E18*((1+HLOOKUP('Monthly CF'!E$2,Revenue!$S$8:$AC$10,3,0))^(1/12))) -> 0 | G18: =IF(G$1=1,Revenue!$P6*Revenue!$A$23,'Monthly CF'!F18*((1+HLOOKUP('Monthly CF'!F$2,Revenue!$S$8:$AC$10,3,0))^(1/12))) -> 0 | H18: =IF(H$1=1,Revenue!$P6*Revenue!$A$23,'Monthly CF'!G18*((1+HLOOKUP('Monthly CF'!G$2,Revenue!$S$8:$AC$10,3,0))^(1/12))) -> 0 | I18: =IF(I$1=1,Revenue!$P6*Revenue!$A$23,'Monthly CF'!H18*((1+HLOOKUP('Monthly CF'!H$2,Revenue!$S$8:$AC$10,3,0))^(1/12))) -> 0 | J18: =IF(J$1=1,Revenue!$P6*Revenue!$A$23,'Monthly CF'!I18*((1+HLOOKUP('Monthly CF'!I$2,Revenue!$S$8:$AC$10,3,0))^(1/12))) -> 0 | K18: =IF(K$1=1,Revenue!$P6*Revenue!$A$23,'Monthly CF'!J18*((1+HLOOKUP('Monthly CF'!J$2,Revenue!$S$8:$AC$10,3,0))^(1/12))) -> 0 | ... EE18: =IF(EE$1=1,Revenue!$P6*Revenue!$A$23,'Monthly CF'!ED18*((1+HLOOKUP('Monthly CF'!ED$2,Revenue!$S$8:$AC$10,3,0))^(1/12))) -> 0
