Workbook

Sheet Dashboard
B2: ESG Energy & Water Savings Tracker
B3: As of: July 24, 2026 | All figures from property renovation capital initiatives
B4: PORTFOLIO-WIDE IMPACT (Completed Initiatives)
B5: Annual kWh Saved | D5: Annual Gallons Saved | F5: Annual $ Savings | H5: Total Capital Deployed
B6: =SUM('Property Summary'!I5:I77) -> 1180312.5 | D6: =SUM('Property Summary'!J5:J77) -> 5418750 | F6: =SUM('Property Summary'!K5:K77) -> 303018.75 | H6: =SUM('Property Summary'!L5:L77) -> 0
B7: Average Portfolio Payback | D7: Properties with Initiatives | F7: Total Initiatives Logged | H7: Completed Initiatives
B8: =IFERROR(SUM('Property Summary'!L5:L77)/SUM('Property Summary'!K5:K77),"-") -> 0 | D8: {=IF(COUNTIF('Initiative Log'!$F$6:$F$205,"Portfolio-Wide")>0,COUNTIF('Portfolio List'!$I$4:$I$76,"<="&_xlfn.MAXIFS('Initiative Log'!$C$6:$C$205,'Initiative Log'!$F$6:$F$205,"Portfolio-Wide")),IFERROR(COUNTA(_xlfn.UNIQUE(_xlfn._xlws.FILTER('Initiative Log'!$D$6:$D$205,'Initiative Log'!$D$6:$D$205<>""))),0))} -> 1 | F8: =COUNTA('Initiative Log'!D6:D205) -> 10 | H8: =COUNTIF('Initiative Log'!K6:K205,"Completed") -> 10
B11: SAVINGS BY FUND
B12: Fund | C12: Properties | D12: Completed Initiatives | E12: Annual kWh Saved | F12: Annual Gal Saved | G12: Annual $ Savings | H12: Total Capital | I12: Payback (yrs)
B13: Fund 1 | C13: =COUNTIF('Property Summary'!$C$5:$C$77,$B13) -> 19 | D13: =SUMIF('Property Summary'!$C$5:$C$77,$B13,'Property Summary'!$H$5:$H$77) -> 0 | E13: =SUMIF('Property Summary'!$C$5:$C$77,$B13,'Property Summary'!$I$5:$I$77) -> 0 | F13: =SUMIF('Property Summary'!$C$5:$C$77,$B13,'Property Summary'!$J$5:$J$77) -> 0 | G13: =SUMIF('Property Summary'!$C$5:$C$77,$B13,'Property Summary'!$K$5:$K$77) -> 0 | H13: =SUMIF('Property Summary'!$C$5:$C$77,$B13,'Property Summary'!$L$5:$L$77) -> 0 | I13: =IFERROR(H13/G13,"-") -> -
B14: Fund 5 | C14: =COUNTIF('Property Summary'!$C$5:$C$77,$B14) -> 2 | D14: =SUMIF('Property Summary'!$C$5:$C$77,$B14,'Property Summary'!$H$5:$H$77) -> 0 | E14: =SUMIF('Property Summary'!$C$5:$C$77,$B14,'Property Summary'!$I$5:$I$77) -> 0 | F14: =SUMIF('Property Summary'!$C$5:$C$77,$B14,'Property Summary'!$J$5:$J$77) -> 0 | G14: =SUMIF('Property Summary'!$C$5:$C$77,$B14,'Property Summary'!$K$5:$K$77) -> 0 | H14: =SUMIF('Property Summary'!$C$5:$C$77,$B14,'Property Summary'!$L$5:$L$77) -> 0 | I14: =IFERROR(H14/G14,"-") -> -
B15: Fund 3 | C15: =COUNTIF('Property Summary'!$C$5:$C$77,$B15) -> 19 | D15: =SUMIF('Property Summary'!$C$5:$C$77,$B15,'Property Summary'!$H$5:$H$77) -> 0 | E15: =SUMIF('Property Summary'!$C$5:$C$77,$B15,'Property Summary'!$I$5:$I$77) -> 0 | F15: =SUMIF('Property Summary'!$C$5:$C$77,$B15,'Property Summary'!$J$5:$J$77) -> 0 | G15: =SUMIF('Property Summary'!$C$5:$C$77,$B15,'Property Summary'!$K$5:$K$77) -> 0 | H15: =SUMIF('Property Summary'!$C$5:$C$77,$B15,'Property Summary'!$L$5:$L$77) -> 0 | I15: =IFERROR(H15/G15,"-") -> -
B16: Fund 4 | C16: =COUNTIF('Property Summary'!$C$5:$C$77,$B16) -> 15 | D16: =SUMIF('Property Summary'!$C$5:$C$77,$B16,'Property Summary'!$H$5:$H$77) -> 0 | E16: =SUMIF('Property Summary'!$C$5:$C$77,$B16,'Property Summary'!$I$5:$I$77) -> 0 | F16: =SUMIF('Property Summary'!$C$5:$C$77,$B16,'Property Summary'!$J$5:$J$77) -> 0 | G16: =SUMIF('Property Summary'!$C$5:$C$77,$B16,'Property Summary'!$K$5:$K$77) -> 0 | H16: =SUMIF('Property Summary'!$C$5:$C$77,$B16,'Property Summary'!$L$5:$L$77) -> 0 | I16: =IFERROR(H16/G16,"-") -> -
B17: Fund 6 | C17: =COUNTIF('Property Summary'!$C$5:$C$77,$B17) -> 13 | D17: =SUMIF('Property Summary'!$C$5:$C$77,$B17,'Property Summary'!$H$5:$H$77) -> 0 | E17: =SUMIF('Property Summary'!$C$5:$C$77,$B17,'Property Summary'!$I$5:$I$77) -> 0 | F17: =SUMIF('Property Summary'!$C$5:$C$77,$B17,'Property Summary'!$J$5:$J$77) -> 0 | G17: =SUMIF('Property Summary'!$C$5:$C$77,$B17,'Property Summary'!$K$5:$K$77) -> 0 | H17: =SUMIF('Property Summary'!$C$5:$C$77,$B17,'Property Summary'!$L$5:$L$77) -> 0 | I17: =IFERROR(H17/G17,"-") -> -
B18: Fund 2 | C18: =COUNTIF('Property Summary'!$C$5:$C$77,$B18) -> 4 | D18: =SUMIF('Property Summary'!$C$5:$C$77,$B18,'Property Summary'!$H$5:$H$77) -> 0 | E18: =SUMIF('Property Summary'!$C$5:$C$77,$B18,'Property Summary'!$I$5:$I$77) -> 0 | F18: =SUMIF('Property Summary'!$C$5:$C$77,$B18,'Property Summary'!$J$5:$J$77) -> 0 | G18: =SUMIF('Property Summary'!$C$5:$C$77,$B18,'Property Summary'!$K$5:$K$77) -> 0 | H18: =SUMIF('Property Summary'!$C$5:$C$77,$B18,'Property Summary'!$L$5:$L$77) -> 0 | I18: =IFERROR(H18/G18,"-") -> -
B21: SAVINGS BY REGION
B22: Fund | C22: Properties | D22: Completed Initiatives | E22: Annual kWh Saved | F22: Annual Gal Saved | G22: Annual $ Savings | H22: Total Capital | I22: Payback (yrs)
B23: Region 1 | C23: =COUNTIF('Property Summary'!$D$5:$D$77,$B23) -> 22 | D23: =SUMIF('Property Summary'!$D$5:$D$77,$B23,'Property Summary'!$H$5:$H$77) -> 0 | E23: =SUMIF('Property Summary'!$D$5:$D$77,$B23,'Property Summary'!$I$5:$I$77) -> 0 | F23: =SUMIF('Property Summary'!$D$5:$D$77,$B23,'Property Summary'!$J$5:$J$77) -> 0 | G23: =SUMIF('Property Summary'!$D$5:$D$77,$B23,'Property Summary'!$K$5:$K$77) -> 0 | H23: =SUMIF('Property Summary'!$D$5:$D$77,$B23,'Property Summary'!$L$5:$L$77) -> 0 | I23: =IFERROR(H23/G23,"-") -> -
B24: Region 4 | C24: =COUNTIF('Property Summary'!$D$5:$D$77,$B24) -> 5 | D24: =SUMIF('Property Summary'!$D$5:$D$77,$B24,'Property Summary'!$H$5:$H$77) -> 0 | E24: =SUMIF('Property Summary'!$D$5:$D$77,$B24,'Property Summary'!$I$5:$I$77) -> 0 | F24: =SUMIF('Property Summary'!$D$5:$D$77,$B24,'Property Summary'!$J$5:$J$77) -> 0 | G24: =SUMIF('Property Summary'!$D$5:$D$77,$B24,'Property Summary'!$K$5:$K$77) -> 0 | H24: =SUMIF('Property Summary'!$D$5:$D$77,$B24,'Property Summary'!$L$5:$L$77) -> 0 | I24: =IFERROR(H24/G24,"-") -> -
B25: Region 3 | C25: =COUNTIF('Property Summary'!$D$5:$D$77,$B25) -> 18 | D25: =SUMIF('Property Summary'!$D$5:$D$77,$B25,'Property Summary'!$H$5:$H$77) -> 0 | E25: =SUMIF('Property Summary'!$D$5:$D$77,$B25,'Property Summary'!$I$5:$I$77) -> 0 | F25: =SUMIF('Property Summary'!$D$5:$D$77,$B25,'Property Summary'!$J$5:$J$77) -> 0 | G25: =SUMIF('Property Summary'!$D$5:$D$77,$B25,'Property Summary'!$K$5:$K$77) -> 0 | H25: =SUMIF('Property Summary'!$D$5:$D$77,$B25,'Property Summary'!$L$5:$L$77) -> 0 | I25: =IFERROR(H25/G25,"-") -> -
B26: Region 5 | C26: =COUNTIF('Property Summary'!$D$5:$D$77,$B26) -> 4 | D26: =SUMIF('Property Summary'!$D$5:$D$77,$B26,'Property Summary'!$H$5:$H$77) -> 0 | E26: =SUMIF('Property Summary'!$D$5:$D$77,$B26,'Property Summary'!$I$5:$I$77) -> 0 | F26: =SUMIF('Property Summary'!$D$5:$D$77,$B26,'Property Summary'!$J$5:$J$77) -> 0 | G26: =SUMIF('Property Summary'!$D$5:$D$77,$B26,'Property Summary'!$K$5:$K$77) -> 0 | H26: =SUMIF('Property Summary'!$D$5:$D$77,$B26,'Property Summary'!$L$5:$L$77) -> 0 | I26: =IFERROR(H26/G26,"-") -> -
B27: Region 6 | C27: =COUNTIF('Property Summary'!$D$5:$D$77,$B27) -> 4 | D27: =SUMIF('Property Summary'!$D$5:$D$77,$B27,'Property Summary'!$H$5:$H$77) -> 0 | E27: =SUMIF('Property Summary'!$D$5:$D$77,$B27,'Property Summary'!$I$5:$I$77) -> 0 | F27: =SUMIF('Property Summary'!$D$5:$D$77,$B27,'Property Summary'!$J$5:$J$77) -> 0 | G27: =SUMIF('Property Summary'!$D$5:$D$77,$B27,'Property Summary'!$K$5:$K$77) -> 0 | H27: =SUMIF('Property Summary'!$D$5:$D$77,$B27,'Property Summary'!$L$5:$L$77) -> 0 | I27: =IFERROR(H27/G27,"-") -> -
B28: Region 2 | C28: =COUNTIF('Property Summary'!$D$5:$D$77,$B28) -> 15 | D28: =SUMIF('Property Summary'!$D$5:$D$77,$B28,'Property Summary'!$H$5:$H$77) -> 0 | E28: =SUMIF('Property Summary'!$D$5:$D$77,$B28,'Property Summary'!$I$5:$I$77) -> 0 | F28: =SUMIF('Property Summary'!$D$5:$D$77,$B28,'Property Summary'!$J$5:$J$77) -> 0 | G28: =SUMIF('Property Summary'!$D$5:$D$77,$B28,'Property Summary'!$K$5:$K$77) -> 0 | H28: =SUMIF('Property Summary'!$D$5:$D$77,$B28,'Property Summary'!$L$5:$L$77) -> 0 | I28: =IFERROR(H28/G28,"-") -> -
B29: Region 7 | C29: =COUNTIF('Property Summary'!$D$5:$D$77,$B29) -> 4 | D29: =SUMIF('Property Summary'!$D$5:$D$77,$B29,'Property Summary'!$H$5:$H$77) -> 0 | E29: =SUMIF('Property Summary'!$D$5:$D$77,$B29,'Property Summary'!$I$5:$I$77) -> 0 | F29: =SUMIF('Property Summary'!$D$5:$D$77,$B29,'Property Summary'!$J$5:$J$77) -> 0 | G29: =SUMIF('Property Summary'!$D$5:$D$77,$B29,'Property Summary'!$K$5:$K$77) -> 0 | H29: =SUMIF('Property Summary'!$D$5:$D$77,$B29,'Property Summary'!$L$5:$L$77) -> 0 | I29: =IFERROR(H29/G29,"-") -> -
B32: SAVINGS BY INITIATIVE TYPE
B33: Initiative Type | C33: # Completed | D33: Annual kWh Saved | E33: Annual Gal Saved | F33: Annual Energy $ | G33: Annual Water $ | H33: Total Annual $ | I33: Total Capital
B34: LED Lighting | C34: =COUNTIFS('Initiative Log'!$I:$I,"LED Lighting",'Initiative Log'!$K:$K,"Completed") -> 1 | D34: =SUMIFS('Initiative Log'!$P:$P,'Initiative Log'!$I:$I,"LED Lighting",'Initiative Log'!$K:$K,"Completed") -> 205312.5 | E34: =SUMIFS('Initiative Log'!$Q:$Q,'Initiative Log'!$I:$I,"LED Lighting",'Initiative Log'!$K:$K,"Completed") -> 0 | F34: =SUMIFS('Initiative Log'!$T:$T,'Initiative Log'!$I:$I,"LED Lighting",'Initiative Log'!$K:$K,"Completed") -> 45168.75 | G34: =SUMIFS('Initiative Log'!$U:$U,'Initiative Log'!$I:$I,"LED Lighting",'Initiative Log'!$K:$K,"Completed") -> 0 | H34: =SUMIFS('Initiative Log'!$V:$V,'Initiative Log'!$I:$I,"LED Lighting",'Initiative Log'!$K:$K,"Completed") -> 45168.75 | I34: =SUMIFS('Initiative Log'!$O:$O,'Initiative Log'!$I:$I,"LED Lighting",'Initiative Log'!$K:$K,"Completed") -> 0
B35: Low-Flow Toilet | C35: =COUNTIFS('Initiative Log'!$I:$I,"Low-Flow Toilet",'Initiative Log'!$K:$K,"Completed") -> 1 | D35: =SUMIFS('Initiative Log'!$P:$P,'Initiative Log'!$I:$I,"Low-Flow Toilet",'Initiative Log'!$K:$K,"Completed") -> 0 | E35: =SUMIFS('Initiative Log'!$Q:$Q,'Initiative Log'!$I:$I,"Low-Flow Toilet",'Initiative Log'!$K:$K,"Completed") -> 1500000 | F35: =SUMIFS('Initiative Log'!$T:$T,'Initiative Log'!$I:$I,"Low-Flow Toilet",'Initiative Log'!$K:$K,"Completed") -> 0 | G35: =SUMIFS('Initiative Log'!$U:$U,'Initiative Log'!$I:$I,"Low-Flow Toilet",'Initiative Log'!$K:$K,"Completed") -> 12000 | H35: =SUMIFS('Initiative Log'!$V:$V,'Initiative Log'!$I:$I,"Low-Flow Toilet",'Initiative Log'!$K:$K,"Completed") -> 12000 | I35: =SUMIFS('Initiative Log'!$O:$O,'Initiative Log'!$I:$I,"Low-Flow Toilet",'Initiative Log'!$K:$K,"Completed") -> 0
B36: Low-Flow Faucet (Bathroom) | C36: =COUNTIFS('Initiative Log'!$I:$I,"Low-Flow Faucet (Bathroom)",'Initiative Log'!$K:$K,"Completed") -> 1 | D36: =SUMIFS('Initiative Log'!$P:$P,'Initiative Log'!$I:$I,"Low-Flow Faucet (Bathroom)",'Initiative Log'!$K:$K,"Completed") -> 0 | E36: =SUMIFS('Initiative Log'!$Q:$Q,'Initiative Log'!$I:$I,"Low-Flow Faucet (Bathroom)",'Initiative Log'!$K:$K,"Completed") -> 618750 | F36: =SUMIFS('Initiative Log'!$T:$T,'Initiative Log'!$I:$I,"Low-Flow Faucet (Bathroom)",'Initiative Log'!$K:$K,"Completed") -> 0 | G36: =SUMIFS('Initiative Log'!$U:$U,'Initiative Log'!$I:$I,"Low-Flow Faucet (Bathroom)",'Initiative Log'!$K:$K,"Completed") -> 4950 | H36: =SUMIFS('Initiative Log'!$V:$V,'Initiative Log'!$I:$I,"Low-Flow Faucet (Bathroom)",'Initiative Log'!$K:$K,"Completed") -> 4950 | I36: =SUMIFS('Initiative Log'!$O:$O,'Initiative Log'!$I:$I,"Low-Flow Faucet (Bathroom)",'Initiative Log'!$K:$K,"Completed") -> 0
B37: Low-Flow Faucet (Kitchen) | C37: =COUNTIFS('Initiative Log'!$I:$I,"Low-Flow Faucet (Kitchen)",'Initiative Log'!$K:$K,"Completed") -> 1 | D37: =SUMIFS('Initiative Log'!$P:$P,'Initiative Log'!$I:$I,"Low-Flow Faucet (Kitchen)",'Initiative Log'!$K:$K,"Completed") -> 0 | E37: =SUMIFS('Initiative Log'!$Q:$Q,'Initiative Log'!$I:$I,"Low-Flow Faucet (Kitchen)",'Initiative Log'!$K:$K,"Completed") -> 825000 | F37: =SUMIFS('Initiative Log'!$T:$T,'Initiative Log'!$I:$I,"Low-Flow Faucet (Kitchen)",'Initiative Log'!$K:$K,"Completed") -> 0 | G37: =SUMIFS('Initiative Log'!$U:$U,'Initiative Log'!$I:$I,"Low-Flow Faucet (Kitchen)",'Initiative Log'!$K:$K,"Completed") -> 6600 | H37: =SUMIFS('Initiative Log'!$V:$V,'Initiative Log'!$I:$I,"Low-Flow Faucet (Kitchen)",'Initiative Log'!$K:$K,"Completed") -> 6600 | I37: =SUMIFS('Initiative Log'!$O:$O,'Initiative Log'!$I:$I,"Low-Flow Faucet (Kitchen)",'Initiative Log'!$K:$K,"Completed") -> 0
B38: Energy Star Refrigerator | C38: =COUNTIFS('Initiative Log'!$I:$I,"Energy Star Refrigerator",'Initiative Log'!$K:$K,"Completed") -> 1 | D38: =SUMIFS('Initiative Log'!$P:$P,'Initiative Log'!$I:$I,"Energy Star Refrigerator",'Initiative Log'!$K:$K,"Completed") -> 150000 | E38: =SUMIFS('Initiative Log'!$Q:$Q,'Initiative Log'!$I:$I,"Energy Star Refrigerator",'Initiative Log'!$K:$K,"Completed") -> 0 | F38: =SUMIFS('Initiative Log'!$T:$T,'Initiative Log'!$I:$I,"Energy Star Refrigerator",'Initiative Log'!$K:$K,"Completed") -> 33000 | G38: =SUMIFS('Initiative Log'!$U:$U,'Initiative Log'!$I:$I,"Energy Star Refrigerator",'Initiative Log'!$K:$K,"Completed") -> 0 | H38: =SUMIFS('Initiative Log'!$V:$V,'Initiative Log'!$I:$I,"Energy Star Refrigerator",'Initiative Log'!$K:$K,"Completed") -> 33000 | I38: =SUMIFS('Initiative Log'!$O:$O,'Initiative Log'!$I:$I,"Energy Star Refrigerator",'Initiative Log'!$K:$K,"Completed") -> 0
B39: Energy Star Range | C39: =COUNTIFS('Initiative Log'!$I:$I,"Energy Star Range",'Initiative Log'!$K:$K,"Completed") -> 1 | D39: =SUMIFS('Initiative Log'!$P:$P,'Initiative Log'!$I:$I,"Energy Star Range",'Initiative Log'!$K:$K,"Completed") -> 112500 | E39: =SUMIFS('Initiative Log'!$Q:$Q,'Initiative Log'!$I:$I,"Energy Star Range",'Initiative Log'!$K:$K,"Completed") -> 0 | F39: =SUMIFS('Initiative Log'!$T:$T,'Initiative Log'!$I:$I,"Energy Star Range",'Initiative Log'!$K:$K,"Completed") -> 24750 | G39: =SUMIFS('Initiative Log'!$U:$U,'Initiative Log'!$I:$I,"Energy Star Range",'Initiative Log'!$K:$K,"Completed") -> 0 | H39: =SUMIFS('Initiative Log'!$V:$V,'Initiative Log'!$I:$I,"Energy Star Range",'Initiative Log'!$K:$K,"Completed") -> 24750 | I39: =SUMIFS('Initiative Log'!$O:$O,'Initiative Log'!$I:$I,"Energy Star Range",'Initiative Log'!$K:$K,"Completed") -> 0
B40: Energy Star Dishwasher | C40: =COUNTIFS('Initiative Log'!$I:$I,"Energy Star Dishwasher",'Initiative Log'!$K:$K,"Completed") -> 1 | D40: =SUMIFS('Initiative Log'!$P:$P,'Initiative Log'!$I:$I,"Energy Star Dishwasher",'Initiative Log'!$K:$K,"Completed") -> 22500 | E40: =SUMIFS('Initiative Log'!$Q:$Q,'Initiative Log'!$I:$I,"Energy Star Dishwasher",'Initiative Log'!$K:$K,"Completed") -> 337500 | F40: =SUMIFS('Initiative Log'!$T:$T,'Initiative Log'!$I:$I,"Energy Star Dishwasher",'Initiative Log'!$K:$K,"Completed") -> 4950 | G40: =SUMIFS('Initiative Log'!$U:$U,'Initiative Log'!$I:$I,"Energy Star Dishwasher",'Initiative Log'!$K:$K,"Completed") -> 2700 | H40: =SUMIFS('Initiative Log'!$V:$V,'Initiative Log'!$I:$I,"Energy Star Dishwasher",'Initiative Log'!$K:$K,"Completed") -> 7650 | I40: =SUMIFS('Initiative Log'!$O:$O,'Initiative Log'!$I:$I,"Energy Star Dishwasher",'Initiative Log'!$K:$K,"Completed") -> 0
B41: Energy Star Washer/Dryer | C41: =COUNTIFS('Initiative Log'!$I:$I,"Energy Star Washer/Dryer",'Initiative Log'!$K:$K,"Completed") -> 1 | D41: =SUMIFS('Initiative Log'!$P:$P,'Initiative Log'!$I:$I,"Energy Star Washer/Dryer",'Initiative Log'!$K:$K,"Completed") -> 502500 | E41: =SUMIFS('Initiative Log'!$Q:$Q,'Initiative Log'!$I:$I,"Energy Star Washer/Dryer",'Initiative Log'!$K:$K,"Completed") -> 112500 | F41: =SUMIFS('Initiative Log'!$T:$T,'Initiative Log'!$I:$I,"Energy Star Washer/Dryer",'Initiative Log'!$K:$K,"Completed") -> 110550 | G41: =SUMIFS('Initiative Log'!$U:$U,'Initiative Log'!$I:$I,"Energy Star Washer/Dryer",'Initiative Log'!$K:$K,"Completed") -> 900 | H41: =SUMIFS('Initiative Log'!$V:$V,'Initiative Log'!$I:$I,"Energy Star Washer/Dryer",'Initiative Log'!$K:$K,"Completed") -> 111450 | I41: =SUMIFS('Initiative Log'!$O:$O,'Initiative Log'!$I:$I,"Energy Star Washer/Dryer",'Initiative Log'!$K:$K,"Completed") -> 0
B42: Energy Star AC Unit | C42: =COUNTIFS('Initiative Log'!$I:$I,"Energy Star AC Unit",'Initiative Log'!$K:$K,"Completed") -> 1 | D42: =SUMIFS('Initiative Log'!$P:$P,'Initiative Log'!$I:$I,"Energy Star AC Unit",'Initiative Log'!$K:$K,"Completed") -> 187500 | E42: =SUMIFS('Initiative Log'!$Q:$Q,'Initiative Log'!$I:$I,"Energy Star AC Unit",'Initiative Log'!$K:$K,"Completed") -> 0 | F42: =SUMIFS('Initiative Log'!$T:$T,'Initiative Log'!$I:$I,"Energy Star AC Unit",'Initiative Log'!$K:$K,"Completed") -> 41250 | G42: =SUMIFS('Initiative Log'!$U:$U,'Initiative Log'!$I:$I,"Energy Star AC Unit",'Initiative Log'!$K:$K,"Completed") -> 0 | H42: =SUMIFS('Initiative Log'!$V:$V,'Initiative Log'!$I:$I,"Energy Star AC Unit",'Initiative Log'!$K:$K,"Completed") -> 41250 | I42: =SUMIFS('Initiative Log'!$O:$O,'Initiative Log'!$I:$I,"Energy Star AC Unit",'Initiative Log'!$K:$K,"Completed") -> 0
B43: Low-Flow Shower Head | C43: =COUNTIFS('Initiative Log'!$I:$I,"Low-Flow Shower Head",'Initiative Log'!$K:$K,"Completed") -> 1 | D43: =SUMIFS('Initiative Log'!$P:$P,'Initiative Log'!$I:$I,"Low-Flow Shower Head",'Initiative Log'!$K:$K,"Completed") -> 0 | E43: =SUMIFS('Initiative Log'!$Q:$Q,'Initiative Log'!$I:$I,"Low-Flow Shower Head",'Initiative Log'!$K:$K,"Completed") -> 2025000 | F43: =SUMIFS('Initiative Log'!$T:$T,'Initiative Log'!$I:$I,"Low-Flow Shower Head",'Initiative Log'!$K:$K,"Completed") -> 0 | G43: =SUMIFS('Initiative Log'!$U:$U,'Initiative Log'!$I:$I,"Low-Flow Shower Head",'Initiative Log'!$K:$K,"Completed") -> 16200 | H43: =SUMIFS('Initiative Log'!$V:$V,'Initiative Log'!$I:$I,"Low-Flow Shower Head",'Initiative Log'!$K:$K,"Completed") -> 16200
B44: Other | C44: =COUNTIFS('Initiative Log'!$I:$I,"Other",'Initiative Log'!$K:$K,"Completed") -> 0 | D44: =SUMIFS('Initiative Log'!$P:$P,'Initiative Log'!$I:$I,"Other",'Initiative Log'!$K:$K,"Completed") -> 0 | E44: =SUMIFS('Initiative Log'!$Q:$Q,'Initiative Log'!$I:$I,"Other",'Initiative Log'!$K:$K,"Completed") -> 0 | F44: =SUMIFS('Initiative Log'!$T:$T,'Initiative Log'!$I:$I,"Other",'Initiative Log'!$K:$K,"Completed") -> 0 | G44: =SUMIFS('Initiative Log'!$U:$U,'Initiative Log'!$I:$I,"Other",'Initiative Log'!$K:$K,"Completed") -> 0 | H44: =SUMIFS('Initiative Log'!$V:$V,'Initiative Log'!$I:$I,"Other",'Initiative Log'!$K:$K,"Completed") -> 0 | I44: =SUMIFS('Initiative Log'!$O:$O,'Initiative Log'!$I:$I,"Other",'Initiative Log'!$K:$K,"Completed") -> 0
B47: WATER CONSERVATION
B48: Initiative Type | C48: # Completed | D48: Baseline Water Use (gal/yr) | E48: Current Water Use (gal/yr) | F48: Water Saved (gal/yr) | G48: Water Saved (%) | H48: Annual Water $ Savings
B49: Low-Flow Toilet | C49: =COUNTIFS('Initiative Log'!$I:$I,"Low-Flow Toilet",'Initiative Log'!$K:$K,"Completed") -> 1 | D49: =SUMIFS('Initiative Log'!$Y:$Y,'Initiative Log'!$I:$I,"Low-Flow Toilet",'Initiative Log'!$K:$K,"Completed") -> 2700000 | E49: =SUMIFS('Initiative Log'!$Z:$Z,'Initiative Log'!$I:$I,"Low-Flow Toilet",'Initiative Log'!$K:$K,"Completed") -> 1200000 | F49: =SUMIFS('Initiative Log'!$Q:$Q,'Initiative Log'!$I:$I,"Low-Flow Toilet",'Initiative Log'!$K:$K,"Completed") -> 1500000 | G49: =IFERROR(F49/D49,"-") -> 0.55555556 | H49: =SUMIFS('Initiative Log'!$U:$U,'Initiative Log'!$I:$I,"Low-Flow Toilet",'Initiative Log'!$K:$K,"Completed") -> 12000
...

Sheet Property Summary
B2: Property-Level ESG Savings Summary - Completed Initiatives
B3: Auto-calculated from Initiative Log (Completed initiatives only).
B4: Property | C4: Fund | D4: Region | E4: State | F4: Total Units | G4: # Initiatives (All) | H4: # Completed | I4: Annual kWh Saved | J4: Annual Gal Saved | K4: Annual $ Savings | L4: Total Capital Cost | M4: kWh / Unit | N4: Payback (yrs) | O4: Baseline Water (gal/yr) | P4: New Water (gal/yr)
B5: Prop 1 | C5: =IFERROR(VLOOKUP(B5,'Portfolio List'!$B$4:$I$76,5,FALSE()),"") -> Fund 1 | D5: =IFERROR(VLOOKUP(B5,'Portfolio List'!$B$4:$I$76,6,FALSE()),"") -> Region 1 | E5: =IFERROR(VLOOKUP(B5,'Portfolio List'!$B$4:$I$76,7,FALSE()),"") -> State 1 | F5: =IFERROR(VLOOKUP(B5,'Portfolio List'!$B$4:$I$76,4,FALSE()),"") -> 180 | G5: =COUNTIF('Initiative Log'!$D:$D,B5) -> 0 | H5: =COUNTIFS('Initiative Log'!$D:$D,B5,'Initiative Log'!$K:$K,"Completed") -> 0 | I5: =SUMIFS('Initiative Log'!$P:$P,'Initiative Log'!$D:$D,B5,'Initiative Log'!$K:$K,"Completed") -> 0 | J5: =SUMIFS('Initiative Log'!$Q:$Q,'Initiative Log'!$D:$D,B5,'Initiative Log'!$K:$K,"Completed") -> 0 | K5: =SUMIFS('Initiative Log'!$V:$V,'Initiative Log'!$D:$D,B5,'Initiative Log'!$K:$K,"Completed") -> 0 | L5: =SUMIFS('Initiative Log'!$O:$O,'Initiative Log'!$D:$D,B5) -> 0 | M5: =IFERROR(I5/F5,0) -> 0 | N5: =IFERROR(IF(OR(L5<=0,K5<=0),"",L5/K5),"-") | O5: =SUMIFS('Initiative Log'!$Y:$Y,'Initiative Log'!$D:$D,B5,'Initiative Log'!$K:$K,"Completed") -> 0 | P5: =SUMIFS('Initiative Log'!$Z:$Z,'Initiative Log'!$D:$D,B5,'Initiative Log'!$K:$K,"Completed") -> 0
B6: Prop 2 | C6: =IFERROR(VLOOKUP(B6,'Portfolio List'!$B$4:$I$76,5,FALSE()),"") -> Fund 1 | D6: =IFERROR(VLOOKUP(B6,'Portfolio List'!$B$4:$I$76,6,FALSE()),"") -> Region 1 | E6: =IFERROR(VLOOKUP(B6,'Portfolio List'!$B$4:$I$76,7,FALSE()),"") -> State 1 | F6: =IFERROR(VLOOKUP(B6,'Portfolio List'!$B$4:$I$76,4,FALSE()),"") -> 112 | G6: =COUNTIF('Initiative Log'!$D:$D,B6) -> 0 | H6: =COUNTIFS('Initiative Log'!$D:$D,B6,'Initiative Log'!$K:$K,"Completed") -> 0 | I6: =SUMIFS('Initiative Log'!$P:$P,'Initiative Log'!$D:$D,B6,'Initiative Log'!$K:$K,"Completed") -> 0 | J6: =SUMIFS('Initiative Log'!$Q:$Q,'Initiative Log'!$D:$D,B6,'Initiative Log'!$K:$K,"Completed") -> 0 | K6: =SUMIFS('Initiative Log'!$V:$V,'Initiative Log'!$D:$D,B6,'Initiative Log'!$K:$K,"Completed") -> 0 | L6: =SUMIFS('Initiative Log'!$O:$O,'Initiative Log'!$D:$D,B6) -> 0 | M6: =IFERROR(I6/F6,0) -> 0 | N6: =IFERROR(IF(OR(L6<=0,K6<=0),"",L6/K6),"-") | O6: =SUMIFS('Initiative Log'!$Y:$Y,'Initiative Log'!$D:$D,B6,'Initiative Log'!$K:$K,"Completed") -> 0 | P6: =SUMIFS('Initiative Log'!$Z:$Z,'Initiative Log'!$D:$D,B6,'Initiative Log'!$K:$K,"Completed") -> 0
B7: Prop 3 | C7: =IFERROR(VLOOKUP(B7,'Portfolio List'!$B$4:$I$76,5,FALSE()),"") -> Fund 1 | D7: =IFERROR(VLOOKUP(B7,'Portfolio List'!$B$4:$I$76,6,FALSE()),"") -> Region 1 | E7: =IFERROR(VLOOKUP(B7,'Portfolio List'!$B$4:$I$76,7,FALSE()),"") -> State 1 | F7: =IFERROR(VLOOKUP(B7,'Portfolio List'!$B$4:$I$76,4,FALSE()),"") -> 128 | G7: =COUNTIF('Initiative Log'!$D:$D,B7) -> 0 | H7: =COUNTIFS('Initiative Log'!$D:$D,B7,'Initiative Log'!$K:$K,"Completed") -> 0 | I7: =SUMIFS('Initiative Log'!$P:$P,'Initiative Log'!$D:$D,B7,'Initiative Log'!$K:$K,"Completed") -> 0 | J7: =SUMIFS('Initiative Log'!$Q:$Q,'Initiative Log'!$D:$D,B7,'Initiative Log'!$K:$K,"Completed") -> 0 | K7: =SUMIFS('Initiative Log'!$V:$V,'Initiative Log'!$D:$D,B7,'Initiative Log'!$K:$K,"Completed") -> 0 | L7: =SUMIFS('Initiative Log'!$O:$O,'Initiative Log'!$D:$D,B7) -> 0 | M7: =IFERROR(I7/F7,0) -> 0 | N7: =IFERROR(IF(OR(L7<=0,K7<=0),"",L7/K7),"-") | O7: =SUMIFS('Initiative Log'!$Y:$Y,'Initiative Log'!$D:$D,B7,'Initiative Log'!$K:$K,"Completed") -> 0 | P7: =SUMIFS('Initiative Log'!$Z:$Z,'Initiative Log'!$D:$D,B7,'Initiative Log'!$K:$K,"Completed") -> 0
B8: Prop 4 | C8: =IFERROR(VLOOKUP(B8,'Portfolio List'!$B$4:$I$76,5,FALSE()),"") -> Fund 1 | D8: =IFERROR(VLOOKUP(B8,'Portfolio List'!$B$4:$I$76,6,FALSE()),"") -> Region 1 | E8: =IFERROR(VLOOKUP(B8,'Portfolio List'!$B$4:$I$76,7,FALSE()),"") -> State 1 | F8: =IFERROR(VLOOKUP(B8,'Portfolio List'!$B$4:$I$76,4,FALSE()),"") -> 320 | G8: =COUNTIF('Initiative Log'!$D:$D,B8) -> 0 | H8: =COUNTIFS('Initiative Log'!$D:$D,B8,'Initiative Log'!$K:$K,"Completed") -> 0 | I8: =SUMIFS('Initiative Log'!$P:$P,'Initiative Log'!$D:$D,B8,'Initiative Log'!$K:$K,"Completed") -> 0 | J8: =SUMIFS('Initiative Log'!$Q:$Q,'Initiative Log'!$D:$D,B8,'Initiative Log'!$K:$K,"Completed") -> 0 | K8: =SUMIFS('Initiative Log'!$V:$V,'Initiative Log'!$D:$D,B8,'Initiative Log'!$K:$K,"Completed") -> 0 | L8: =SUMIFS('Initiative Log'!$O:$O,'Initiative Log'!$D:$D,B8) -> 0 | M8: =IFERROR(I8/F8,0) -> 0 | N8: =IFERROR(IF(OR(L8<=0,K8<=0),"",L8/K8),"-") | O8: =SUMIFS('Initiative Log'!$Y:$Y,'Initiative Log'!$D:$D,B8,'Initiative Log'!$K:$K,"Completed") -> 0 | P8: =SUMIFS('Initiative Log'!$Z:$Z,'Initiative Log'!$D:$D,B8,'Initiative Log'!$K:$K,"Completed") -> 0
B9: Prop 5 | C9: =IFERROR(VLOOKUP(B9,'Portfolio List'!$B$4:$I$76,5,FALSE()),"") -> Fund 1 | D9: =IFERROR(VLOOKUP(B9,'Portfolio List'!$B$4:$I$76,6,FALSE()),"") -> Region 1 | E9: =IFERROR(VLOOKUP(B9,'Portfolio List'!$B$4:$I$76,7,FALSE()),"") -> State 1 | F9: =IFERROR(VLOOKUP(B9,'Portfolio List'!$B$4:$I$76,4,FALSE()),"") -> 300 | G9: =COUNTIF('Initiative Log'!$D:$D,B9) -> 0 | H9: =COUNTIFS('Initiative Log'!$D:$D,B9,'Initiative Log'!$K:$K,"Completed") -> 0 | I9: =SUMIFS('Initiative Log'!$P:$P,'Initiative Log'!$D:$D,B9,'Initiative Log'!$K:$K,"Completed") -> 0 | J9: =SUMIFS('Initiative Log'!$Q:$Q,'Initiative Log'!$D:$D,B9,'Initiative Log'!$K:$K,"Completed") -> 0 | K9: =SUMIFS('Initiative Log'!$V:$V,'Initiative Log'!$D:$D,B9,'Initiative Log'!$K:$K,"Completed") -> 0 | L9: =SUMIFS('Initiative Log'!$O:$O,'Initiative Log'!$D:$D,B9) -> 0 | M9: =IFERROR(I9/F9,0) -> 0 | N9: =IFERROR(IF(OR(L9<=0,K9<=0),"",L9/K9),"-") | O9: =SUMIFS('Initiative Log'!$Y:$Y,'Initiative Log'!$D:$D,B9,'Initiative Log'!$K:$K,"Completed") -> 0 | P9: =SUMIFS('Initiative Log'!$Z:$Z,'Initiative Log'!$D:$D,B9,'Initiative Log'!$K:$K,"Completed") -> 0
B10: Prop 6 | C10: =IFERROR(VLOOKUP(B10,'Portfolio List'!$B$4:$I$76,5,FALSE()),"") -> Fund 1 | D10: =IFERROR(VLOOKUP(B10,'Portfolio List'!$B$4:$I$76,6,FALSE()),"") -> Region 1 | E10: =IFERROR(VLOOKUP(B10,'Portfolio List'!$B$4:$I$76,7,FALSE()),"") -> State 1 | F10: =IFERROR(VLOOKUP(B10,'Portfolio List'!$B$4:$I$76,4,FALSE()),"") -> 144 | G10: =COUNTIF('Initiative Log'!$D:$D,B10) -> 0 | H10: =COUNTIFS('Initiative Log'!$D:$D,B10,'Initiative Log'!$K:$K,"Completed") -> 0 | I10: =SUMIFS('Initiative Log'!$P:$P,'Initiative Log'!$D:$D,B10,'Initiative Log'!$K:$K,"Completed") -> 0 | J10: =SUMIFS('Initiative Log'!$Q:$Q,'Initiative Log'!$D:$D,B10,'Initiative Log'!$K:$K,"Completed") -> 0 | K10: =SUMIFS('Initiative Log'!$V:$V,'Initiative Log'!$D:$D,B10,'Initiative Log'!$K:$K,"Completed") -> 0 | L10: =SUMIFS('Initiative Log'!$O:$O,'Initiative Log'!$D:$D,B10) -> 0 | M10: =IFERROR(I10/F10,0) -> 0 | N10: =IFERROR(IF(OR(L10<=0,K10<=0),"",L10/K10),"-") | O10: =SUMIFS('Initiative Log'!$Y:$Y,'Initiative Log'!$D:$D,B10,'Initiative Log'!$K:$K,"Completed") -> 0 | P10: =SUMIFS('Initiative Log'!$Z:$Z,'Initiative Log'!$D:$D,B10,'Initiative Log'!$K:$K,"Completed") -> 0
B11: Prop 7 | C11: =IFERROR(VLOOKUP(B11,'Portfolio List'!$B$4:$I$76,5,FALSE()),"") -> Fund 1 | D11: =IFERROR(VLOOKUP(B11,'Portfolio List'!$B$4:$I$76,6,FALSE()),"") -> Region 2 | E11: =IFERROR(VLOOKUP(B11,'Portfolio List'!$B$4:$I$76,7,FALSE()),"") -> State 1 | F11: =IFERROR(VLOOKUP(B11,'Portfolio List'!$B$4:$I$76,4,FALSE()),"") -> 482 | G11: =COUNTIF('Initiative Log'!$D:$D,B11) -> 0 | H11: =COUNTIFS('Initiative Log'!$D:$D,B11,'Initiative Log'!$K:$K,"Completed") -> 0 | I11: =SUMIFS('Initiative Log'!$P:$P,'Initiative Log'!$D:$D,B11,'Initiative Log'!$K:$K,"Completed") -> 0 | J11: =SUMIFS('Initiative Log'!$Q:$Q,'Initiative Log'!$D:$D,B11,'Initiative Log'!$K:$K,"Completed") -> 0 | K11: =SUMIFS('Initiative Log'!$V:$V,'Initiative Log'!$D:$D,B11,'Initiative Log'!$K:$K,"Completed") -> 0 | L11: =SUMIFS('Initiative Log'!$O:$O,'Initiative Log'!$D:$D,B11) -> 0 | M11: =IFERROR(I11/F11,0) -> 0 | N11: =IFERROR(IF(OR(L11<=0,K11<=0),"",L11/K11),"-") | O11: =SUMIFS('Initiative Log'!$Y:$Y,'Initiative Log'!$D:$D,B11,'Initiative Log'!$K:$K,"Completed") -> 0 | P11: =SUMIFS('Initiative Log'!$Z:$Z,'Initiative Log'!$D:$D,B11,'Initiative Log'!$K:$K,"Completed") -> 0
B12: Prop 8 | C12: =IFERROR(VLOOKUP(B12,'Portfolio List'!$B$4:$I$76,5,FALSE()),"") -> Fund 1 | D12: =IFERROR(VLOOKUP(B12,'Portfolio List'!$B$4:$I$76,6,FALSE()),"") -> Region 1 | E12: =IFERROR(VLOOKUP(B12,'Portfolio List'!$B$4:$I$76,7,FALSE()),"") -> State 1 | F12: =IFERROR(VLOOKUP(B12,'Portfolio List'!$B$4:$I$76,4,FALSE()),"") -> 44 | G12: =COUNTIF('Initiative Log'!$D:$D,B12) -> 0 | H12: =COUNTIFS('Initiative Log'!$D:$D,B12,'Initiative Log'!$K:$K,"Completed") -> 0 | I12: =SUMIFS('Initiative Log'!$P:$P,'Initiative Log'!$D:$D,B12,'Initiative Log'!$K:$K,"Completed") -> 0 | J12: =SUMIFS('Initiative Log'!$Q:$Q,'Initiative Log'!$D:$D,B12,'Initiative Log'!$K:$K,"Completed") -> 0 | K12: =SUMIFS('Initiative Log'!$V:$V,'Initiative Log'!$D:$D,B12,'Initiative Log'!$K:$K,"Completed") -> 0 | L12: =SUMIFS('Initiative Log'!$O:$O,'Initiative Log'!$D:$D,B12) -> 0 | M12: =IFERROR(I12/F12,0) -> 0 | N12: =IFERROR(IF(OR(L12<=0,K12<=0),"",L12/K12),"-") | O12: =SUMIFS('Initiative Log'!$Y:$Y,'Initiative Log'!$D:$D,B12,'Initiative Log'!$K:$K,"Completed") -> 0 | P12: =SUMIFS('Initiative Log'!$Z:$Z,'Initiative Log'!$D:$D,B12,'Initiative Log'!$K:$K,"Completed") -> 0
B13: Prop 9 | C13: =IFERROR(VLOOKUP(B13,'Portfolio List'!$B$4:$I$76,5,FALSE()),"") -> Fund 1 | D13: =IFERROR(VLOOKUP(B13,'Portfolio List'!$B$4:$I$76,6,FALSE()),"") -> Region 1 | E13: =IFERROR(VLOOKUP(B13,'Portfolio List'!$B$4:$I$76,7,FALSE()),"") -> State 1 | F13: =IFERROR(VLOOKUP(B13,'Portfolio List'!$B$4:$I$76,4,FALSE()),"") -> 184 | G13: =COUNTIF('Initiative Log'!$D:$D,B13) -> 0 | H13: =COUNTIFS('Initiative Log'!$D:$D,B13,'Initiative Log'!$K:$K,"Completed") -> 0 | I13: =SUMIFS('Initiative Log'!$P:$P,'Initiative Log'!$D:$D,B13,'Initiative Log'!$K:$K,"Completed") -> 0 | J13: =SUMIFS('Initiative Log'!$Q:$Q,'Initiative Log'!$D:$D,B13,'Initiative Log'!$K:$K,"Completed") -> 0 | K13: =SUMIFS('Initiative Log'!$V:$V,'Initiative Log'!$D:$D,B13,'Initiative Log'!$K:$K,"Completed") -> 0 | L13: =SUMIFS('Initiative Log'!$O:$O,'Initiative Log'!$D:$D,B13) -> 0 | M13: =IFERROR(I13/F13,0) -> 0 | N13: =IFERROR(IF(OR(L13<=0,K13<=0),"",L13/K13),"-") | O13: =SUMIFS('Initiative Log'!$Y:$Y,'Initiative Log'!$D:$D,B13,'Initiative Log'!$K:$K,"Completed") -> 0 | P13: =SUMIFS('Initiative Log'!$Z:$Z,'Initiative Log'!$D:$D,B13,'Initiative Log'!$K:$K,"Completed") -> 0
B14: Prop 10 | C14: =IFERROR(VLOOKUP(B14,'Portfolio List'!$B$4:$I$76,5,FALSE()),"") -> Fund 1 | D14: =IFERROR(VLOOKUP(B14,'Portfolio List'!$B$4:$I$76,6,FALSE()),"") -> Region 1 | E14: =IFERROR(VLOOKUP(B14,'Portfolio List'!$B$4:$I$76,7,FALSE()),"") -> State 1 | F14: =IFERROR(VLOOKUP(B14,'Portfolio List'!$B$4:$I$76,4,FALSE()),"") -> 45 | G14: =COUNTIF('Initiative Log'!$D:$D,B14) -> 0 | H14: =COUNTIFS('Initiative Log'!$D:$D,B14,'Initiative Log'!$K:$K,"Completed") -> 0 | I14: =SUMIFS('Initiative Log'!$P:$P,'Initiative Log'!$D:$D,B14,'Initiative Log'!$K:$K,"Completed") -> 0 | J14: =SUMIFS('Initiative Log'!$Q:$Q,'Initiative Log'!$D:$D,B14,'Initiative Log'!$K:$K,"Completed") -> 0 | K14: =SUMIFS('Initiative Log'!$V:$V,'Initiative Log'!$D:$D,B14,'Initiative Log'!$K:$K,"Completed") -> 0 | L14: =SUMIFS('Initiative Log'!$O:$O,'Initiative Log'!$D:$D,B14) -> 0 | M14: =IFERROR(I14/F14,0) -> 0 | N14: =IFERROR(IF(OR(L14<=0,K14<=0),"",L14/K14),"-") | O14: =SUMIFS('Initiative Log'!$Y:$Y,'Initiative Log'!$D:$D,B14,'Initiative Log'!$K:$K,"Completed") -> 0 | P14: =SUMIFS('Initiative Log'!$Z:$Z,'Initiative Log'!$D:$D,B14,'Initiative Log'!$K:$K,"Completed") -> 0
B15: Prop 11 | C15: =IFERROR(VLOOKUP(B15,'Portfolio List'!$B$4:$I$76,5,FALSE()),"") -> Fund 2 | D15: =IFERROR(VLOOKUP(B15,'Portfolio List'!$B$4:$I$76,6,FALSE()),"") -> Region 1 | E15: =IFERROR(VLOOKUP(B15,'Portfolio List'!$B$4:$I$76,7,FALSE()),"") -> State 1 | F15: =IFERROR(VLOOKUP(B15,'Portfolio List'!$B$4:$I$76,4,FALSE()),"") -> 232 | G15: =COUNTIF('Initiative Log'!$D:$D,B15) -> 0 | H15: =COUNTIFS('Initiative Log'!$D:$D,B15,'Initiative Log'!$K:$K,"Completed") -> 0 | I15: =SUMIFS('Initiative Log'!$P:$P,'Initiative Log'!$D:$D,B15,'Initiative Log'!$K:$K,"Completed") -> 0 | J15: =SUMIFS('Initiative Log'!$Q:$Q,'Initiative Log'!$D:$D,B15,'Initiative Log'!$K:$K,"Completed") -> 0 | K15: =SUMIFS('Initiative Log'!$V:$V,'Initiative Log'!$D:$D,B15,'Initiative Log'!$K:$K,"Completed") -> 0 | L15: =SUMIFS('Initiative Log'!$O:$O,'Initiative Log'!$D:$D,B15) -> 0 | M15: =IFERROR(I15/F15,0) -> 0 | N15: =IFERROR(IF(OR(L15<=0,K15<=0),"",L15/K15),"-") | O15: =SUMIFS('Initiative Log'!$Y:$Y,'Initiative Log'!$D:$D,B15,'Initiative Log'!$K:$K,"Completed") -> 0 | P15: =SUMIFS('Initiative Log'!$Z:$Z,'Initiative Log'!$D:$D,B15,'Initiative Log'!$K:$K,"Completed") -> 0
B16: Prop 12 | C16: =IFERROR(VLOOKUP(B16,'Portfolio List'!$B$4:$I$76,5,FALSE()),"") -> Fund 1 | D16: =IFERROR(VLOOKUP(B16,'Portfolio List'!$B$4:$I$76,6,FALSE()),"") -> Region 1 | E16: =IFERROR(VLOOKUP(B16,'Portfolio List'!$B$4:$I$76,7,FALSE()),"") -> State 1 | F16: =IFERROR(VLOOKUP(B16,'Portfolio List'!$B$4:$I$76,4,FALSE()),"") -> 44 | G16: =COUNTIF('Initiative Log'!$D:$D,B16) -> 0 | H16: =COUNTIFS('Initiative Log'!$D:$D,B16,'Initiative Log'!$K:$K,"Completed") -> 0 | I16: =SUMIFS('Initiative Log'!$P:$P,'Initiative Log'!$D:$D,B16,'Initiative Log'!$K:$K,"Completed") -> 0 | J16: =SUMIFS('Initiative Log'!$Q:$Q,'Initiative Log'!$D:$D,B16,'Initiative Log'!$K:$K,"Completed") -> 0 | K16: =SUMIFS('Initiative Log'!$V:$V,'Initiative Log'!$D:$D,B16,'Initiative Log'!$K:$K,"Completed") -> 0 | L16: =SUMIFS('Initiative Log'!$O:$O,'Initiative Log'!$D:$D,B16) -> 0 | M16: =IFERROR(I16/F16,0) -> 0 | N16: =IFERROR(IF(OR(L16<=0,K16<=0),"",L16/K16),"-") | O16: =SUMIFS('Initiative Log'!$Y:$Y,'Initiative Log'!$D:$D,B16,'Initiative Log'!$K:$K,"Completed") -> 0 | P16: =SUMIFS('Initiative Log'!$Z:$Z,'Initiative Log'!$D:$D,B16,'Initiative Log'!$K:$K,"Completed") -> 0
... B77: Prop 73 | C77: =IFERROR(VLOOKUP(B77,'Portfolio List'!$B$4:$I$76,5,FALSE()),"") -> Fund 7 | D77: =IFERROR(VLOOKUP(B77,'Portfolio List'!$B$4:$I$76,6,FALSE()),"") -> Region 8 | E77: =IFERROR(VLOOKUP(B77,'Portfolio List'!$B$4:$I$76,7,FALSE()),"") -> State 1 | F77: =IFERROR(VLOOKUP(B77,'Portfolio List'!$B$4:$I$76,4,FALSE()),"") -> 750 | G77: =COUNTIF('Initiative Log'!$D:$D,B77) -> 10 | H77: =COUNTIFS('Initiative Log'!$D:$D,B77,'Initiative Log'!$K:$K,"Completed") -> 10 | I77: =SUMIFS('Initiative Log'!$P:$P,'Initiative Log'!$D:$D,B77,'Initiative Log'!$K:$K,"Completed") -> 1180312.5 | J77: =SUMIFS('Initiative Log'!$Q:$Q,'Initiative Log'!$D:$D,B77,'Initiative Log'!$K:$K,"Completed") -> 5418750 | K77: =SUMIFS('Initiative Log'!$V:$V,'Initiative Log'!$D:$D,B77,'Initiative Log'!$K:$K,"Completed") -> 303018.75 | L77: =SUMIFS('Initiative Log'!$O:$O,'Initiative Log'!$D:$D,B77) -> 0 | M77: =IFERROR(I77/F77,0) -> 1573.75 | N77: =IFERROR(IF(OR(L77<=0,K77<=0),"",L77/K77),"-") | O77: =SUMIFS('Initiative Log'!$Y:$Y,'Initiative Log'!$D:$D,B77,'Initiative Log'!$K:$K,"Completed") -> 20418750 | P77: =SUMIFS('Initiative Log'!$Z:$Z,'Initiative Log'!$D:$D,B77,'Initiative Log'!$K:$K,"Completed") -> 15000000
B78: PORTFOLIO TOTAL | F78: =SUM(F5:F77) -> 13899 | G78: =SUM(G5:G77) -> 10 | H78: =SUM(H5:H77) -> 10 | I78: =SUM(I5:I77) -> 1180312.5 | J78: =SUM(J5:J77) -> 5418750 | K78: =SUM(K5:K77) -> 303018.75 | L78: =SUM(L5:L77) -> 0 | O78: =SUM(O5:O77) -> 20418750 | P78: =SUM(P5:P77) -> 15000000

Sheet Initiative Log
B2: ESG Initiative Log
B3: Enter one row per ESG initiative per property. Blue text = editable input cells. Black text = auto-calculated formulas - do not edit.
B4: ID | C4: DATE | D4: PROPERTY INFO | I4: INITIATIVE | K4: STATUS | M4: QUANTITY INPUTS | O4: COST | P4: SAVINGS CALCULATION | T4: ANNUAL $ IMPACT | W4: PAYBACK | X4: NOTES | Y4: BEFORE & AFTER WATER | AA4: PERIOD | AC4: RENOVATION PROGRESS
B5: # | C5: Date Logged | D5: Property | E5: Fund | F5: Region | G5: State | H5: Total Units | I5: Initiative Type | J5: Category | K5: Status | L5: Completion Date | M5: Qty | N5: Hrs/Day (LED) | O5: Upfront Cost ($) | P5: Annual kWh Saved | Q5: Annual Gal Saved | R5: Elec Rate ($/kWh) | S5: Water Rate ($/gal) | T5: Annual Energy $ Savings | U5: Annual Water $ Savings | V5: Total Annual $ Savings | W5: Payback (yrs) | X5: Notes | Y5: Baseline Water (gal/yr) | Z5: New Water (gal/yr) | AA5: Fiscal Year | AB5: Quarter | AC5: Unit Type | AD5: Units Planned | AE5: Units Renovated | AF5: % Complete
B6: 1 | C6: 45974 | D6: Prop 73 | E6: =IF(D6="","",IFERROR(VLOOKUP(D6,'Portfolio List'!$B$4:$I$76,5,FALSE()),"")) -> Fund 7 | F6: =IF(D6="","",IFERROR(VLOOKUP(D6,'Portfolio List'!$B$4:$I$76,6,FALSE()),"")) -> Region 8 | G6: =IF(D6="","",IFERROR(VLOOKUP(D6,'Portfolio List'!$B$4:$I$76,7,FALSE()),"")) -> State 1 | H6: =IF(D6="","",IFERROR(VLOOKUP(D6,'Portfolio List'!$B$4:$I$76,4,FALSE()),"")) -> 750 | I6: LED Lighting | J6: =IF(I6="","",IF(OR(I6="LED Lighting",I6="Energy Star Refrigerator",I6="Energy Star Range",I6="Energy Star AC Unit"),"Energy",IF(OR(I6="Low-Flow Toilet",I6="Low-Flow Faucet (Bathroom)",I6="Low-Flow Faucet (Kitchen)",I6="Low-Flow Shower Head"),"Water",IF(OR(I6="Energy Star Dishwasher",I6="Energy Star Washer/Dryer"),"Both","Other")))) -> Energy | K6: Completed | L6: 45974 | M6: 750 | N6: 3 | P6: =IF(D6="",0,IF(I6="LED Lighting",M6*IF(AC6="Studio",Assumptions!$C$15,IF(AC6="1 Bedroom",Assumptions!$C$16,IF(AC6="2 Bedroom",Assumptions!$C$17,IF(AC6="3 Bedroom",Assumptions!$C$18,Assumptions!$C$16))))*N6*365/1000,IFERROR(VLOOKUP(I6,Assumptions!$B$40:$H$50,2,FALSE()),0)*M6)) -> 205312.5 | Q6: =IF(D6="",0,IFERROR(VLOOKUP(I6,Assumptions!$B$40:$H$50,3,FALSE()),0)*M6) -> 0 | R6: =IF(G6="",0.2161,IFERROR(VLOOKUP(G6,Assumptions!$B$53:$C$61,2,FALSE())/100,0.2161)) -> 0.22 | S6: =IF(G6="",0,IFERROR(VLOOKUP(G6,Assumptions!$B$64:$C$72,2,FALSE())/1000,0.008)) -> 0.008 | T6: =IF(D6="","",P6*R6) -> 45168.75 | U6: =IF(D6="","",Q6*S6) -> 0 | V6: =IF(D6="","",T6+U6) -> 45168.75 | W6: =IF(OR(D6="",O6="",O6<=0,V6="",V6<=0),"",IFERROR(O6/V6,"")) | Y6: =IF(D6="","",IFERROR(VLOOKUP(I6,Assumptions!$B$40:$H$50,6,FALSE()),0)*M6) -> 0 | Z6: =IF(D6="","",IFERROR(VLOOKUP(I6,Assumptions!$B$40:$H$50,7,FALSE()),0)*M6) -> 0 | AA6: =IF(L6="","",YEAR(L6)) -> 2025 | AB6: =IF(L6="","","Q"&INT((MONTH(L6)+2)/3)) -> Q4 | AC6: 1 Bedroom | AD6: 750 | AE6: 750 | AF6: =IFERROR(AE6/AD6,"-") -> 1
B7: =IF($D7="","",B6+1) -> 2 | C7: 45974 | D7: Prop 73 | E7: =IF(D7="","",IFERROR(VLOOKUP(D7,'Portfolio List'!$B$4:$I$76,5,FALSE()),"")) -> Fund 7 | F7: =IF(D7="","",IFERROR(VLOOKUP(D7,'Portfolio List'!$B$4:$I$76,6,FALSE()),"")) -> Region 8 | G7: =IF(D7="","",IFERROR(VLOOKUP(D7,'Portfolio List'!$B$4:$I$76,7,FALSE()),"")) -> State 1 | H7: =IF(D7="","",IFERROR(VLOOKUP(D7,'Portfolio List'!$B$4:$I$76,4,FALSE()),"")) -> 750 | I7: Low-Flow Toilet | J7: =IF(I7="","",IF(OR(I7="LED Lighting",I7="Energy Star Refrigerator",I7="Energy Star Range",I7="Energy Star AC Unit"),"Energy",IF(OR(I7="Low-Flow Toilet",I7="Low-Flow Faucet (Bathroom)",I7="Low-Flow Faucet (Kitchen)",I7="Low-Flow Shower Head"),"Water",IF(OR(I7="Energy Star Dishwasher",I7="Energy Star Washer/Dryer"),"Both","Other")))) -> Water | K7: Completed | L7: 45974 | M7: 750 | P7: =IF(D7="",0,IF(I7="LED Lighting",M7*IF(AC7="Studio",Assumptions!$C$15,IF(AC7="1 Bedroom",Assumptions!$C$16,IF(AC7="2 Bedroom",Assumptions!$C$17,IF(AC7="3 Bedroom",Assumptions!$C$18,Assumptions!$C$16))))*N7*365/1000,IFERROR(VLOOKUP(I7,Assumptions!$B$40:$H$50,2,FALSE()),0)*M7)) -> 0 | Q7: =IF(D7="",0,IFERROR(VLOOKUP(I7,Assumptions!$B$40:$H$50,3,FALSE()),0)*M7) -> 1500000 | R7: =IF(G7="",0.2161,IFERROR(VLOOKUP(G7,Assumptions!$B$53:$C$61,2,FALSE())/100,0.2161)) -> 0.22 | S7: =IF(G7="",0,IFERROR(VLOOKUP(G7,Assumptions!$B$64:$C$72,2,FALSE())/1000,0.008)) -> 0.008 | T7: =IF(D7="","",P7*R7) -> 0 | U7: =IF(D7="","",Q7*S7) -> 12000 | V7: =IF(D7="","",T7+U7) -> 12000 | W7: =IF(OR(D7="",O7="",O7<=0,V7="",V7<=0),"",IFERROR(O7/V7,"")) | Y7: =IF(D7="","",IFERROR(VLOOKUP(I7,Assumptions!$B$40:$H$50,6,FALSE()),0)*M7) -> 2700000 | Z7: =IF(D7="","",IFERROR(VLOOKUP(I7,Assumptions!$B$40:$H$50,7,FALSE()),0)*M7) -> 1200000 | AA7: =IF(L7="","",YEAR(L7)) -> 2025 | AB7: =IF(L7="","","Q"&INT((MONTH(L7)+2)/3)) -> Q4 | AC7: 1 Bedroom | AD7: 750 | AE7: 750 | AF7: =IFERROR(AE7/AD7,"-") -> 1
B8: =IF($D8="","",B7+1) -> 3 | C8: 45974 | D8: Prop 73 | E8: =IF(D8="","",IFERROR(VLOOKUP(D8,'Portfolio List'!$B$4:$I$76,5,FALSE()),"")) -> Fund 7 | F8: =IF(D8="","",IFERROR(VLOOKUP(D8,'Portfolio List'!$B$4:$I$76,6,FALSE()),"")) -> Region 8 | G8: =IF(D8="","",IFERROR(VLOOKUP(D8,'Portfolio List'!$B$4:$I$76,7,FALSE()),"")) -> State 1 | H8: =IF(D8="","",IFERROR(VLOOKUP(D8,'Portfolio List'!$B$4:$I$76,4,FALSE()),"")) -> 750 | I8: Low-Flow Faucet (Bathroom) | J8: =IF(I8="","",IF(OR(I8="LED Lighting",I8="Energy Star Refrigerator",I8="Energy Star Range",I8="Energy Star AC Unit"),"Energy",IF(OR(I8="Low-Flow Toilet",I8="Low-Flow Faucet (Bathroom)",I8="Low-Flow Faucet (Kitchen)",I8="Low-Flow Shower Head"),"Water",IF(OR(I8="Energy Star Dishwasher",I8="Energy Star Washer/Dryer"),"Both","Other")))) -> Water | K8: Completed | L8: 45974 | M8: 750 | P8: =IF(D8="",0,IF(I8="LED Lighting",M8*IF(AC8="Studio",Assumptions!$C$15,IF(AC8="1 Bedroom",Assumptions!$C$16,IF(AC8="2 Bedroom",Assumptions!$C$17,IF(AC8="3 Bedroom",Assumptions!$C$18,Assumptions!$C$16))))*N8*365/1000,IFERROR(VLOOKUP(I8,Assumptions!$B$40:$H$50,2,FALSE()),0)*M8)) -> 0 | Q8: =IF(D8="",0,IFERROR(VLOOKUP(I8,Assumptions!$B$40:$H$50,3,FALSE()),0)*M8) -> 618750 | R8: =IF(G8="",0.2161,IFERROR(VLOOKUP(G8,Assumptions!$B$53:$C$61,2,FALSE())/100,0.2161)) -> 0.22 | S8: =IF(G8="",0,IFERROR(VLOOKUP(G8,Assumptions!$B$64:$C$72,2,FALSE())/1000,0.008)) -> 0.008 | T8: =IF(D8="","",P8*R8) -> 0 | U8: =IF(D8="","",Q8*S8) -> 4950 | V8: =IF(D8="","",T8+U8) -> 4950 | W8: =IF(OR(D8="",O8="",O8<=0,V8="",V8<=0),"",IFERROR(O8/V8,"")) | Y8: =IF(D8="","",IFERROR(VLOOKUP(I8,Assumptions!$B$40:$H$50,6,FALSE()),0)*M8) -> 1968750 | Z8: =IF(D8="","",IFERROR(VLOOKUP(I8,Assumptions!$B$40:$H$50,7,FALSE()),0)*M8) -> 1350000 | AA8: =IF(L8="","",YEAR(L8)) -> 2025 | AB8: =IF(L8="","","Q"&INT((MONTH(L8)+2)/3)) -> Q4 | AC8: 1 Bedroom | AD8: 750 | AE8: 750 | AF8: =IFERROR(AE8/AD8,"-") -> 1
B9: =IF($D9="","",B8+1) -> 4 | C9: 45974 | D9: Prop 73 | E9: =IF(D9="","",IFERROR(VLOOKUP(D9,'Portfolio List'!$B$4:$I$76,5,FALSE()),"")) -> Fund 7 | F9: =IF(D9="","",IFERROR(VLOOKUP(D9,'Portfolio List'!$B$4:$I$76,6,FALSE()),"")) -> Region 8 | G9: =IF(D9="","",IFERROR(VLOOKUP(D9,'Portfolio List'!$B$4:$I$76,7,FALSE()),"")) -> State 1 | H9: =IF(D9="","",IFERROR(VLOOKUP(D9,'Portfolio List'!$B$4:$I$76,4,FALSE()),"")) -> 750 | I9: Low-Flow Faucet (Kitchen) | J9: =IF(I9="","",IF(OR(I9="LED Lighting",I9="Energy Star Refrigerator",I9="Energy Star Range",I9="Energy Star AC Unit"),"Energy",IF(OR(I9="Low-Flow Toilet",I9="Low-Flow Faucet (Bathroom)",I9="Low-Flow Faucet (Kitchen)",I9="Low-Flow Shower Head"),"Water",IF(OR(I9="Energy Star Dishwasher",I9="Energy Star Washer/Dryer"),"Both","Other")))) -> Water | K9: Completed | L9: 45974 | M9: 750 | P9: =IF(D9="",0,IF(I9="LED Lighting",M9*IF(AC9="Studio",Assumptions!$C$15,IF(AC9="1 Bedroom",Assumptions!$C$16,IF(AC9="2 Bedroom",Assumptions!$C$17,IF(AC9="3 Bedroom",Assumptions!$C$18,Assumptions!$C$16))))*N9*365/1000,IFERROR(VLOOKUP(I9,Assumptions!$B$40:$H$50,2,FALSE()),0)*M9)) -> 0 | Q9: =IF(D9="",0,IFERROR(VLOOKUP(I9,Assumptions!$B$40:$H$50,3,FALSE()),0)*M9) -> 825000 | R9: =IF(G9="",0.2161,IFERROR(VLOOKUP(G9,Assumptions!$B$53:$C$61,2,FALSE())/100,0.2161)) -> 0.22 | S9: =IF(G9="",0,IFERROR(VLOOKUP(G9,Assumptions!$B$64:$C$72,2,FALSE())/1000,0.008)) -> 0.008 | T9: =IF(D9="","",P9*R9) -> 0 | U9: =IF(D9="","",Q9*S9) -> 6600 | V9: =IF(D9="","",T9+U9) -> 6600 | W9: =IF(OR(D9="",O9="",O9<=0,V9="",V9<=0),"",IFERROR(O9/V9,"")) | Y9: =IF(D9="","",IFERROR(VLOOKUP(I9,Assumptions!$B$40:$H$50,6,FALSE()),0)*M9) -> 2625000 | Z9: =IF(D9="","",IFERROR(VLOOKUP(I9,Assumptions!$B$40:$H$50,7,FALSE()),0)*M9) -> 1800000 | AA9: =IF(L9="","",YEAR(L9)) -> 2025 | AB9: =IF(L9="","","Q"&INT((MONTH(L9)+2)/3)) -> Q4 | AC9: 1 Bedroom | AD9: 750 | AE9: 750 | AF9: =IFERROR(AE9/AD9,"-") -> 1
B10: =IF($D10="","",B9+1) -> 5 | C10: 45974 | D10: Prop 73 | E10: =IF(D10="","",IFERROR(VLOOKUP(D10,'Portfolio List'!$B$4:$I$76,5,FALSE()),"")) -> Fund 7 | F10: =IF(D10="","",IFERROR(VLOOKUP(D10,'Portfolio List'!$B$4:$I$76,6,FALSE()),"")) -> Region 8 | G10: =IF(D10="","",IFERROR(VLOOKUP(D10,'Portfolio List'!$B$4:$I$76,7,FALSE()),"")) -> State 1 | H10: =IF(D10="","",IFERROR(VLOOKUP(D10,'Portfolio List'!$B$4:$I$76,4,FALSE()),"")) -> 750 | I10: Energy Star Refrigerator | J10: =IF(I10="","",IF(OR(I10="LED Lighting",I10="Energy Star Refrigerator",I10="Energy Star Range",I10="Energy Star AC Unit"),"Energy",IF(OR(I10="Low-Flow Toilet",I10="Low-Flow Faucet (Bathroom)",I10="Low-Flow Faucet (Kitchen)",I10="Low-Flow Shower Head"),"Water",IF(OR(I10="Energy Star Dishwasher",I10="Energy Star Washer/Dryer"),"Both","Other")))) -> Energy | K10: Completed | L10: 45974 | M10: 750 | P10: =IF(D10="",0,IF(I10="LED Lighting",M10*IF(AC10="Studio",Assumptions!$C$15,IF(AC10="1 Bedroom",Assumptions!$C$16,IF(AC10="2 Bedroom",Assumptions!$C$17,IF(AC10="3 Bedroom",Assumptions!$C$18,Assumptions!$C$16))))*N10*365/1000,IFERROR(VLOOKUP(I10,Assumptions!$B$40:$H$50,2,FALSE()),0)*M10)) -> 150000 | Q10: =IF(D10="",0,IFERROR(VLOOKUP(I10,Assumptions!$B$40:$H$50,3,FALSE()),0)*M10) -> 0 | R10: =IF(G10="",0.2161,IFERROR(VLOOKUP(G10,Assumptions!$B$53:$C$61,2,FALSE())/100,0.2161)) -> 0.22 | S10: =IF(G10="",0,IFERROR(VLOOKUP(G10,Assumptions!$B$64:$C$72,2,FALSE())/1000,0.008)) -> 0.008 | T10: =IF(D10="","",P10*R10) -> 33000 | U10: =IF(D10="","",Q10*S10) -> 0 | V10: =IF(D10="","",T10+U10) -> 33000 | W10: =IF(OR(D10="",O10="",O10<=0,V10="",V10<=0),"",IFERROR(O10/V10,"")) | Y10: =IF(D10="","",IFERROR(VLOOKUP(I10,Assumptions!$B$40:$H$50,6,FALSE()),0)*M10) -> 0 | Z10: =IF(D10="","",IFERROR(VLOOKUP(I10,Assumptions!$B$40:$H$50,7,FALSE()),0)*M10) -> 0 | AA10: =IF(L10="","",YEAR(L10)) -> 2025 | AB10: =IF(L10="","","Q"&INT((MONTH(L10)+2)/3)) -> Q4 | AC10: 1 Bedroom | AD10: 750 | AE10: 750 | AF10: =IFERROR(AE10/AD10,"-") -> 1
B11: =IF($D11="","",B10+1) -> 6 | C11: 45974 | D11: Prop 73 | E11: =IF(D11="","",IFERROR(VLOOKUP(D11,'Portfolio List'!$B$4:$I$76,5,FALSE()),"")) -> Fund 7 | F11: =IF(D11="","",IFERROR(VLOOKUP(D11,'Portfolio List'!$B$4:$I$76,6,FALSE()),"")) -> Region 8 | G11: =IF(D11="","",IFERROR(VLOOKUP(D11,'Portfolio List'!$B$4:$I$76,7,FALSE()),"")) -> State 1 | H11: =IF(D11="","",IFERROR(VLOOKUP(D11,'Portfolio List'!$B$4:$I$76,4,FALSE()),"")) -> 750 | I11: Energy Star Range | J11: =IF(I11="","",IF(OR(I11="LED Lighting",I11="Energy Star Refrigerator",I11="Energy Star Range",I11="Energy Star AC Unit"),"Energy",IF(OR(I11="Low-Flow Toilet",I11="Low-Flow Faucet (Bathroom)",I11="Low-Flow Faucet (Kitchen)",I11="Low-Flow Shower Head"),"Water",IF(OR(I11="Energy Star Dishwasher",I11="Energy Star Washer/Dryer"),"Both","Other")))) -> Energy | K11: Completed | L11: 45974 | M11: 750 | P11: =IF(D11="",0,IF(I11="LED Lighting",M11*IF(AC11="Studio",Assumptions!$C$15,IF(AC11="1 Bedroom",Assumptions!$C$16,IF(AC11="2 Bedroom",Assumptions!$C$17,IF(AC11="3 Bedroom",Assumptions!$C$18,Assumptions!$C$16))))*N11*365/1000,IFERROR(VLOOKUP(I11,Assumptions!$B$40:$H$50,2,FALSE()),0)*M11)) -> 112500 | Q11: =IF(D11="",0,IFERROR(VLOOKUP(I11,Assumptions!$B$40:$H$50,3,FALSE()),0)*M11) -> 0 | R11: =IF(G11="",0.2161,IFERROR(VLOOKUP(G11,Assumptions!$B$53:$C$61,2,FALSE())/100,0.2161)) -> 0.22 | S11: =IF(G11="",0,IFERROR(VLOOKUP(G11,Assumptions!$B$64:$C$72,2,FALSE())/1000,0.008)) -> 0.008 | T11: =IF(D11="","",P11*R11) -> 24750 | U11: =IF(D11="","",Q11*S11) -> 0 | V11: =IF(D11="","",T11+U11) -> 24750 | W11: =IF(OR(D11="",O11="",O11<=0,V11="",V11<=0),"",IFERROR(O11/V11,"")) | Y11: =IF(D11="","",IFERROR(VLOOKUP(I11,Assumptions!$B$40:$H$50,6,FALSE()),0)*M11) -> 0 | Z11: =IF(D11="","",IFERROR(VLOOKUP(I11,Assumptions!$B$40:$H$50,7,FALSE()),0)*M11) -> 0 | AA11: =IF(L11="","",YEAR(L11)) -> 2025 | AB11: =IF(L11="","","Q"&INT((MONTH(L11)+2)/3)) -> Q4 | AC11: 1 Bedroom | AD11: 750 | AE11: 750 | AF11: =IFERROR(AE11/AD11,"-") -> 1
B12: =IF($D12="","",B11+1) -> 7 | C12: 45974 | D12: Prop 73 | E12: =IF(D12="","",IFERROR(VLOOKUP(D12,'Portfolio List'!$B$4:$I$76,5,FALSE()),"")) -> Fund 7 | F12: =IF(D12="","",IFERROR(VLOOKUP(D12,'Portfolio List'!$B$4:$I$76,6,FALSE()),"")) -> Region 8 | G12: =IF(D12="","",IFERROR(VLOOKUP(D12,'Portfolio List'!$B$4:$I$76,7,FALSE()),"")) -> State 1 | H12: =IF(D12="","",IFERROR(VLOOKUP(D12,'Portfolio List'!$B$4:$I$76,4,FALSE()),"")) -> 750 | I12: Energy Star Dishwasher | J12: =IF(I12="","",IF(OR(I12="LED Lighting",I12="Energy Star Refrigerator",I12="Energy Star Range",I12="Energy Star AC Unit"),"Energy",IF(OR(I12="Low-Flow Toilet",I12="Low-Flow Faucet (Bathroom)",I12="Low-Flow Faucet (Kitchen)",I12="Low-Flow Shower Head"),"Water",IF(OR(I12="Energy Star Dishwasher",I12="Energy Star Washer/Dryer"),"Both","Other")))) -> Both | K12: Completed | L12: 45974 | M12: 750 | P12: =IF(D12="",0,IF(I12="LED Lighting",M12*IF(AC12="Studio",Assumptions!$C$15,IF(AC12="1 Bedroom",Assumptions!$C$16,IF(AC12="2 Bedroom",Assumptions!$C$17,IF(AC12="3 Bedroom",Assumptions!$C$18,Assumptions!$C$16))))*N12*365/1000,IFERROR(VLOOKUP(I12,Assumptions!$B$40:$H$50,2,FALSE()),0)*M12)) -> 22500 | Q12: =IF(D12="",0,IFERROR(VLOOKUP(I12,Assumptions!$B$40:$H$50,3,FALSE()),0)*M12) -> 337500 | R12: =IF(G12="",0.2161,IFERROR(VLOOKUP(G12,Assumptions!$B$53:$C$61,2,FALSE())/100,0.2161)) -> 0.22 | S12: =IF(G12="",0,IFERROR(VLOOKUP(G12,Assumptions!$B$64:$C$72,2,FALSE())/1000,0.008)) -> 0.008 | T12: =IF(D12="","",P12*R12) -> 4950 | U12: =IF(D12="","",Q12*S12) -> 2700 | V12: =IF(D12="","",T12+U12) -> 7650 | W12: =IF(OR(D12="",O12="",O12<=0,V12="",V12<=0),"",IFERROR(O12/V12,"")) | Y12: =IF(D12="","",IFERROR(VLOOKUP(I12,Assumptions!$B$40:$H$50,6,FALSE()),0)*M12) -> 3750000 | Z12: =IF(D12="","",IFERROR(VLOOKUP(I12,Assumptions!$B$40:$H$50,7,FALSE()),0)*M12) -> 3412500 | AA12: =IF(L12="","",YEAR(L12)) -> 2025 | AB12: =IF(L12="","","Q"&INT((MONTH(L12)+2)/3)) -> Q4 | AC12: 1 Bedroom | AD12: 750 | AE12: 750 | AF12: =IFERROR(AE12/AD12,"-") -> 1
B13: =IF($D13="","",B12+1) -> 8 | C13: 45974 | D13: Prop 73 | E13: =IF(D13="","",IFERROR(VLOOKUP(D13,'Portfolio List'!$B$4:$I$76,5,FALSE()),"")) -> Fund 7 | F13: =IF(D13="","",IFERROR(VLOOKUP(D13,'Portfolio List'!$B$4:$I$76,6,FALSE()),"")) -> Region 8 | G13: =IF(D13="","",IFERROR(VLOOKUP(D13,'Portfolio List'!$B$4:$I$76,7,FALSE()),"")) -> State 1 | H13: =IF(D13="","",IFERROR(VLOOKUP(D13,'Portfolio List'!$B$4:$I$76,4,FALSE()),"")) -> 750 | I13: Energy Star Washer/Dryer | J13: =IF(I13="","",IF(OR(I13="LED Lighting",I13="Energy Star Refrigerator",I13="Energy Star Range",I13="Energy Star AC Unit"),"Energy",IF(OR(I13="Low-Flow Toilet",I13="Low-Flow Faucet (Bathroom)",I13="Low-Flow Faucet (Kitchen)",I13="Low-Flow Shower Head"),"Water",IF(OR(I13="Energy Star Dishwasher",I13="Energy Star Washer/Dryer"),"Both","Other")))) -> Both | K13: Completed | L13: 45974 | M13: 750 | P13: =IF(D13="",0,IF(I13="LED Lighting",M13*IF(AC13="Studio",Assumptions!$C$15,IF(AC13="1 Bedroom",Assumptions!$C$16,IF(AC13="2 Bedroom",Assumptions!$C$17,IF(AC13="3 Bedroom",Assumptions!$C$18,Assumptions!$C$16))))*N13*365/1000,IFERROR(VLOOKUP(I13,Assumptions!$B$40:$H$50,2,FALSE()),0)*M13)) -> 502500 | Q13: =IF(D13="",0,IFERROR(VLOOKUP(I13,Assumptions!$B$40:$H$50,3,FALSE()),0)*M13) -> 112500 | R13: =IF(G13="",0.2161,IFERROR(VLOOKUP(G13,Assumptions!$B$53:$C$61,2,FALSE())/100,0.2161)) -> 0.22 | S13: =IF(G13="",0,IFERROR(VLOOKUP(G13,Assumptions!$B$64:$C$72,2,FALSE())/1000,0.008)) -> 0.008 | T13: =IF(D13="","",P13*R13) -> 110550 | U13: =IF(D13="","",Q13*S13) -> 900 | V13: =IF(D13="","",T13+U13) -> 111450 | W13: =IF(OR(D13="",O13="",O13<=0,V13="",V13<=0),"",IFERROR(O13/V13,"")) | Y13: =IF(D13="","",IFERROR(VLOOKUP(I13,Assumptions!$B$40:$H$50,6,FALSE()),0)*M13) -> 2625000 | Z13: =IF(D13="","",IFERROR(VLOOKUP(I13,Assumptions!$B$40:$H$50,7,FALSE()),0)*M13) -> 2512500 | AA13: =IF(L13="","",YEAR(L13)) -> 2025 | AB13: =IF(L13="","","Q"&INT((MONTH(L13)+2)/3)) -> Q4 | AC13: 1 Bedroom | AD13: 750 | AE13: 750 | AF13: =IFERROR(AE13/AD13,"-") -> 1
B14: =IF($D14="","",B13+1) -> 9 | C14: 45974 | D14: Prop 73 | E14: =IF(D14="","",IFERROR(VLOOKUP(D14,'Portfolio List'!$B$4:$I$76,5,FALSE()),"")) -> Fund 7 | F14: =IF(D14="","",IFERROR(VLOOKUP(D14,'Portfolio List'!$B$4:$I$76,6,FALSE()),"")) -> Region 8 | G14: =IF(D14="","",IFERROR(VLOOKUP(D14,'Portfolio List'!$B$4:$I$76,7,FALSE()),"")) -> State 1 | H14: =IF(D14="","",IFERROR(VLOOKUP(D14,'Portfolio List'!$B$4:$I$76,4,FALSE()),"")) -> 750 | I14: Energy Star AC Unit | J14: =IF(I14="","",IF(OR(I14="LED Lighting",I14="Energy Star Refrigerator",I14="Energy Star Range",I14="Energy Star AC Unit"),"Energy",IF(OR(I14="Low-Flow Toilet",I14="Low-Flow Faucet (Bathroom)",I14="Low-Flow Faucet (Kitchen)",I14="Low-Flow Shower Head"),"Water",IF(OR(I14="Energy Star Dishwasher",I14="Energy Star Washer/Dryer"),"Both","Other")))) -> Energy | K14: Completed | L14: 45974 | M14: 750 | P14: =IF(D14="",0,IF(I14="LED Lighting",M14*IF(AC14="Studio",Assumptions!$C$15,IF(AC14="1 Bedroom",Assumptions!$C$16,IF(AC14="2 Bedroom",Assumptions!$C$17,IF(AC14="3 Bedroom",Assumptions!$C$18,Assumptions!$C$16))))*N14*365/1000,IFERROR(VLOOKUP(I14,Assumptions!$B$40:$H$50,2,FALSE()),0)*M14)) -> 187500 | Q14: =IF(D14="",0,IFERROR(VLOOKUP(I14,Assumptions!$B$40:$H$50,3,FALSE()),0)*M14) -> 0 | R14: =IF(G14="",0.2161,IFERROR(VLOOKUP(G14,Assumptions!$B$53:$C$61,2,FALSE())/100,0.2161)) -> 0.22 | S14: =IF(G14="",0,IFERROR(VLOOKUP(G14,Assumptions!$B$64:$C$72,2,FALSE())/1000,0.008)) -> 0.008 | T14: =IF(D14="","",P14*R14) -> 41250 | U14: =IF(D14="","",Q14*S14) -> 0 | V14: =IF(D14="","",T14+U14) -> 41250 | W14: =IF(OR(D14="",O14="",O14<=0,V14="",V14<=0),"",IFERROR(O14/V14,"")) | Y14: =IF(D14="","",IFERROR(VLOOKUP(I14,Assumptions!$B$40:$H$50,6,FALSE()),0)*M14) -> 0 | Z14: =IF(D14="","",IFERROR(VLOOKUP(I14,Assumptions!$B$40:$H$50,7,FALSE()),0)*M14) -> 0 | AA14: =IF(L14="","",YEAR(L14)) -> 2025 | AB14: =IF(L14="","","Q"&INT((MONTH(L14)+2)/3)) -> Q4 | AC14: 1 Bedroom | AD14: 750 | AE14: 750 | AF14: =IFERROR(AE14/AD14,"-") -> 1
B15: =IF($D15="","",B14+1) -> 10 | C15: 45974 | D15: Prop 73 | E15: =IF(D15="","",IFERROR(VLOOKUP(D15,'Portfolio List'!$B$4:$I$76,5,FALSE()),"")) -> Fund 7 | F15: =IF(D15="","",IFERROR(VLOOKUP(D15,'Portfolio List'!$B$4:$I$76,6,FALSE()),"")) -> Region 8 | G15: =IF(D15="","",IFERROR(VLOOKUP(D15,'Portfolio List'!$B$4:$I$76,7,FALSE()),"")) -> State 1 | H15: =IF(D15="","",IFERROR(VLOOKUP(D15,'Portfolio List'!$B$4:$I$76,4,FALSE()),"")) -> 750 | I15: Low-Flow Shower Head | J15: =IF(I15="","",IF(OR(I15="LED Lighting",I15="Energy Star Refrigerator",I15="Energy Star Range",I15="Energy Star AC Unit"),"Energy",IF(OR(I15="Low-Flow Toilet",I15="Low-Flow Faucet (Bathroom)",I15="Low-Flow Faucet (Kitchen)",I15="Low-Flow Shower Head"),"Water",IF(OR(I15="Energy Star Dishwasher",I15="Energy Star Washer/Dryer"),"Both","Other")))) -> Water | K15: Completed | L15: 45974 | M15: 750 | P15: =IF(D15="",0,IF(I15="LED Lighting",M15*IF(AC15="Studio",Assumptions!$C$15,IF(AC15="1 Bedroom",Assumptions!$C$16,IF(AC15="2 Bedroom",Assumptions!$C$17,IF(AC15="3 Bedroom",Assumptions!$C$18,Assumptions!$C$16))))*N15*365/1000,IFERROR(VLOOKUP(I15,Assumptions!$B$40:$H$50,2,FALSE()),0)*M15)) -> 0 | Q15: =IF(D15="",0,IFERROR(VLOOKUP(I15,Assumptions!$B$40:$H$50,3,FALSE()),0)*M15) -> 2025000 | R15: =IF(G15="",0.2161,IFERROR(VLOOKUP(G15,Assumptions!$B$53:$C$61,2,FALSE())/100,0.2161)) -> 0.22 | S15: =IF(G15="",0,IFERROR(VLOOKUP(G15,Assumptions!$B$64:$C$72,2,FALSE())/1000,0.008)) -> 0.008 | T15: =IF(D15="","",P15*R15) -> 0 | U15: =IF(D15="","",Q15*S15) -> 16200 | V15: =IF(D15="","",T15+U15) -> 16200 | W15: =IF(OR(D15="",O15="",O15<=0,V15="",V15<=0),"",IFERROR(O15/V15,"")) | Y15: =IF(D15="","",IFERROR(VLOOKUP(I15,Assumptions!$B$40:$H$50,6,FALSE()),0)*M15) -> 6750000 | Z15: =IF(D15="","",IFERROR(VLOOKUP(I15,Assumptions!$B$40:$H$50,7,FALSE()),0)*M15) -> 4725000 | AA15: =IF(L15="","",YEAR(L15)) -> 2025 | AB15: =IF(L15="","","Q"&INT((MONTH(L15)+2)/3)) -> Q4 | AC15: 1 Bedroom | AD15: 750 | AE15: 750 | AF15: =IFERROR(AE15/AD15,"-") -> 1
B16: =IF($D16="","",B15+1) | E16: =IF(D16="","",IFERROR(VLOOKUP(D16,'Portfolio List'!$B$4:$I$76,5,FALSE()),"")) | F16: =IF(D16="","",IFERROR(VLOOKUP(D16,'Portfolio List'!$B$4:$I$76,6,FALSE()),"")) | G16: =IF(D16="","",IFERROR(VLOOKUP(D16,'Portfolio List'!$B$4:$I$76,7,FALSE()),"")) | H16: =IF(D16="","",IFERROR(VLOOKUP(D16,'Portfolio List'!$B$4:$I$76,4,FALSE()),"")) | J16: =IF(I16="","",IF(OR(I16="LED Lighting",I16="Energy Star Refrigerator",I16="Energy Star Range",I16="Energy Star AC Unit"),"Energy",IF(OR(I16="Low-Flow Toilet",I16="Low-Flow Faucet (Bathroom)",I16="Low-Flow Faucet (Kitchen)",I16="Low-Flow Shower Head"),"Water",IF(OR(I16="Energy Star Dishwasher",I16="Energy Star Washer/Dryer"),"Both","Other")))) | P16: =IF(D16="",0,IF(I16="LED Lighting",M16*IF(AC16="Studio",Assumptions!$C$15,IF(AC16="1 Bedroom",Assumptions!$C$16,IF(AC16="2 Bedroom",Assumptions!$C$17,IF(AC16="3 Bedroom",Assumptions!$C$18,Assumptions!$C$16))))*N16*365/1000,IFERROR(VLOOKUP(I16,Assumptions!$B$40:$H$50,2,FALSE()),0)*M16)) -> 0 | Q16: =IF(D16="",0,IFERROR(VLOOKUP(I16,Assumptions!$B$40:$H$50,3,FALSE()),0)*M16) -> 0 | R16: =IF(G16="",0.2161,IFERROR(VLOOKUP(G16,Assumptions!$B$53:$C$61,2,FALSE())/100,0.2161)) -> 0.2161 | S16: =IF(G16="",0,IFERROR(VLOOKUP(G16,Assumptions!$B$64:$C$72,2,FALSE())/1000,0.008)) -> 0 | T16: =IF(D16="","",P16*R16) | U16: =IF(D16="","",Q16*S16) | V16: =IF(D16="","",T16+U16) | W16: =IF(OR(D16="",O16="",O16<=0,V16="",V16<=0),"",IFERROR(O16/V16,"")) | Y16: =IF(D16="","",IFERROR(VLOOKUP(I16,Assumptions!$B$40:$H$50,6,FALSE()),0)*M16) | Z16: =IF(D16="","",IFERROR(VLOOKUP(I16,Assumptions!$B$40:$H$50,7,FALSE()),0)*M16) | AA16: =IF(L16="","",YEAR(L16)) | AB16: =IF(L16="","","Q"&INT((MONTH(L16)+2)/3)) | AF16: =IFERROR(AE16/AD16,"-") -> -
B17: =IF($D17="","",B16+1) | E17: =IF(D17="","",IFERROR(VLOOKUP(D17,'Portfolio List'!$B$4:$I$76,5,FALSE()),"")) | F17: =IF(D17="","",IFERROR(VLOOKUP(D17,'Portfolio List'!$B$4:$I$76,6,FALSE()),"")) | G17: =IF(D17="","",IFERROR(VLOOKUP(D17,'Portfolio List'!$B$4:$I$76,7,FALSE()),"")) | H17: =IF(D17="","",IFERROR(VLOOKUP(D17,'Portfolio List'!$B$4:$I$76,4,FALSE()),"")) | J17: =IF(I17="","",IF(OR(I17="LED Lighting",I17="Energy Star Refrigerator",I17="Energy Star Range",I17="Energy Star AC Unit"),"Energy",IF(OR(I17="Low-Flow Toilet",I17="Low-Flow Faucet (Bathroom)",I17="Low-Flow Faucet (Kitchen)",I17="Low-Flow Shower Head"),"Water",IF(OR(I17="Energy Star Dishwasher",I17="Energy Star Washer/Dryer"),"Both","Other")))) | P17: =IF(D17="",0,IF(I17="LED Lighting",M17*IF(AC17="Studio",Assumptions!$C$15,IF(AC17="1 Bedroom",Assumptions!$C$16,IF(AC17="2 Bedroom",Assumptions!$C$17,IF(AC17="3 Bedroom",Assumptions!$C$18,Assumptions!$C$16))))*N17*365/1000,IFERROR(VLOOKUP(I17,Assumptions!$B$40:$H$50,2,FALSE()),0)*M17)) -> 0 | Q17: =IF(D17="",0,IFERROR(VLOOKUP(I17,Assumptions!$B$40:$H$50,3,FALSE()),0)*M17) -> 0 | R17: =IF(G17="",0.2161,IFERROR(VLOOKUP(G17,Assumptions!$B$53:$C$61,2,FALSE())/100,0.2161)) -> 0.2161 | S17: =IF(G17="",0,IFERROR(VLOOKUP(G17,Assumptions!$B$64:$C$72,2,FALSE())/1000,0.008)) -> 0 | T17: =IF(D17="","",P17*R17) | U17: =IF(D17="","",Q17*S17) | V17: =IF(D17="","",T17+U17) | W17: =IF(OR(D17="",O17="",O17<=0,V17="",V17<=0),"",IFERROR(O17/V17,"")) | Y17: =IF(D17="","",IFERROR(VLOOKUP(I17,Assumptions!$B$40:$H$50,6,FALSE()),0)*M17) | Z17: =IF(D17="","",IFERROR(VLOOKUP(I17,Assumptions!$B$40:$H$50,7,FALSE()),0)*M17) | AA17: =IF(L17="","",YEAR(L17)) | AB17: =IF(L17="","","Q"&INT((MONTH(L17)+2)/3)) | AF17: =IFERROR(AE17/AD17,"-") -> -
